Workbook

Sheet Parameters
A1: Parameter | B1: Value | C1: Description
A2: Amazon_Commission_pct_300_500 | B2: 0.05 | C2: Amazon commission rate for >₹300 & ≤₹500 (Beauty/Haircare) - 5%
A3: Amazon_Commission_pct_above_500 | B3: 0.08 | C3: Amazon commission rate for >₹500 (Beauty/Haircare) - 8%
A4: ONDC_Flat_Fee | B4: 1.5 | C4: ONDC flat fee per transaction above ₹250 (INR) - ₹1.50 from Jan 1, 2025
A5: Payment_Fee_pct | B5: 0.02 | C5: Payment gateway fee rate (decimal) - 2%
A6: Packaging_per_unit | B6: 12 | C6: Packaging cost per unit (INR)
A7: Other_Fees_per_unit | B7: 5 | C7: Other fees per unit (INR)
A8: CAC_Amazon_per_unit | B8: 90 | C8: Customer Acquisition Cost per unit - Amazon (INR)
A9: CAC_ONDC_per_unit | B9: 100 | C9: Customer Acquisition Cost per unit - ONDC (INR)
A10: Default_Fixed_Costs_monthly | B10: 50000 | C10: Monthly fixed costs (INR)

Sheet Product_Data
A1: Product_Name | B1: Size | C1: Selling_Price | D1: Estimated_Weight_g | E1: Monthly_Sales_Units | F1: Cost_of_Goods_est | G1: Logistics_Cost | H1: Data_Source
A2: Mamaearth Onion Hair Oil | B2: 100ml | C2: 399 | D2: 100 | E2: 18000 | F2: 119.7 | G2: 15 | H2: final.xlsx
A3: Mamaearth Onion Shampoo | B3: 250ml | C3: 310 | D3: 250 | E3: 23400 | F3: 53.1 | G3: 15 | H3: final.xlsx
A4: Mamaearth Onion Conditioner | B4: 250ml | C4: 349 | D4: 250 | E4: 18000 | F4: 104.7 | G4: 15 | H4: final.xlsx
A5: Rosemary Hair Growth Oil with Rosemary & Methi Dana for Promoting Hair Growth - 100 ml | B5: 100ml | C5: 266 | D5: 100 | E5: 23400 | F5: 30 | G5: 15 | H5: final.xlsx
A6: Mamaearth Rosemary Shampoo | B6: 250ml | C6: 310 | D6: 250 | E6: 18000 | F6: 93 | G6: 15 | H6: final.xlsx
A7: Mamaearth Argan Hair Mask | B7: 200g | C7: 599 | D7: 200 | E7: 18000 | F7: 111.6 | G7: 15 | H7: final.xlsx
A8: Mamaearth Onion Hair Growth Serum (50ml) | B8: 50ml | C8: 599 | D8: 50 | E8: 15000 | F8: 179.7 | G8: 15 | H8: final.xlsx
A9: Mamaearth Vitamin C and Turmeric Face Wash | B9: 100ml | C9: 269 | D9: 100 | E9: 18000 | F9: 119.7 | G9: 15 | H9: final.xlsx
A10: Ubtan Natural Glow Face Wash with Turmeric & Saffron for Tan Removal – 100 ml | B10: 100ml | C10: 269 | D10: 100 | E10: 26000 | F10: 30 | G10: 15 | H10: final.xlsx
A11: Tea Tree Pimple Control Face Wash with Tea Tree & Salicylic for Oily & Acne-Prone Skin - 100ml | B11: 100ml | C11: 269 | D11: 100 | E11: 26000 | F11: 30 | G11: 15 | H11: final.xlsx
A12: Mamaearth Aloe Vera Face Wash | B12: 100ml | C12: 269 | D12: 100 | E12: 22000 | F12: 80.7 | G12: 15 | H12: final.xlsx
A13: Rice Dewy Bright Face Wash With Rice Water & Niacinamide for Glass Skin - 200 ml | B13: 200ml | C13: 549 | D13: 200 | E13: 26000 | F13: 30 | G13: 15 | H13: final.xlsx
... A39: Charcoal Black Long Stay Kajal with Vitamin C & Chamomile for 11-Hour Smudge-free Stay | B39: 100ml | C39: 299 | D39: 100 | E39: 23400 | F39: 30 | G39: 15 | H39: final.xlsx

Sheet Unit_Economics
A1: Product_Name | B1: Selling_Price | C1: Cost_of_Goods | D1: Amazon_Commission_amt | E1: ONDC_Commission_amt | F1: Payment_Gateway_Fee | G1: Logistics_Cost | H1: Packaging_Cost | I1: Other_Fees | J1: CAC_Amazon | K1: CAC_ONDC | L1: Total_Cost_Amazon | M1: Total_Cost_ONDC | N1: Profit_per_unit_Amazon | O1: Profit_per_unit_ONDC | P1: Profit_Change_pct | Q1: Monthly_Profit_Amazon | R1: Monthly_Profit_ONDC
A2: Mamaearth Onion Hair Oil | B2: =Product_Data!C2 | C2: =Product_Data!F2 | D2: =IF(B2<=300, 0, IF(B2<=500, B2*Parameters!B2, B2*Parameters!B3)) | E2: =IF(B2<=250, 0, Parameters!B4) | F2: =B2*Parameters!B5 | G2: =Product_Data!G2 | H2: =Parameters!B6 | I2: =Parameters!B7 | J2: =Parameters!B8 | K2: =Parameters!B9 | L2: =C2+D2+F2+G2+H2+I2+J2 | M2: =C2+E2+F2+G2+H2+I2+K2 | N2: =B2-L2 | O2: =B2-M2 | P2: =IF(ABS(N2)>0, (O2-N2)/ABS(N2)*100, 0) | Q2: =N2*Product_Data!E2 | R2: =O2*Product_Data!E2
A3: Mamaearth Onion Shampoo | B3: =Product_Data!C3 | C3: =Product_Data!F3 | D3: =IF(B3<=300, 0, IF(B3<=500, B3*Parameters!B2, B3*Parameters!B3)) | E3: =IF(B3<=250, 0, Parameters!B4) | F3: =B3*Parameters!B5 | G3: =Product_Data!G3 | H3: =Parameters!B6 | I3: =Parameters!B7 | J3: =Parameters!B8 | K3: =Parameters!B9 | L3: =C3+D3+F3+G3+H3+I3+J3 | M3: =C3+E3+F3+G3+H3+I3+K3 | N3: =B3-L3 | O3: =B3-M3 | P3: =IF(ABS(N3)>0, (O3-N3)/ABS(N3)*100, 0) | Q3: =N3*Product_Data!E3 | R3: =O3*Product_Data!E3
A4: Mamaearth Onion Conditioner | B4: =Product_Data!C4 | C4: =Product_Data!F4 | D4: =IF(B4<=300, 0, IF(B4<=500, B4*Parameters!B2, B4*Parameters!B3)) | E4: =IF(B4<=250, 0, Parameters!B4) | F4: =B4*Parameters!B5 | G4: =Product_Data!G4 | H4: =Parameters!B6 | I4: =Parameters!B7 | J4: =Parameters!B8 | K4: =Parameters!B9 | L4: =C4+D4+F4+G4+H4+I4+J4 | M4: =C4+E4+F4+G4+H4+I4+K4 | N4: =B4-L4 | O4: =B4-M4 | P4: =IF(ABS(N4)>0, (O4-N4)/ABS(N4)*100, 0) | Q4: =N4*Product_Data!E4 | R4: =O4*Product_Data!E4
A5: Rosemary Hair Growth Oil with Rosemary & Methi Dana for Promoting Hair Growth - 100 ml | B5: =Product_Data!C5 | C5: =Product_Data!F5 | D5: =IF(B5<=300, 0, IF(B5<=500, B5*Parameters!B2, B5*Parameters!B3)) | E5: =IF(B5<=250, 0, Parameters!B4) | F5: =B5*Parameters!B5 | G5: =Product_Data!G5 | H5: =Parameters!B6 | I5: =Parameters!B7 | J5: =Parameters!B8 | K5: =Parameters!B9 | L5: =C5+D5+F5+G5+H5+I5+J5 | M5: =C5+E5+F5+G5+H5+I5+K5 | N5: =B5-L5 | O5: =B5-M5 | P5: =IF(ABS(N5)>0, (O5-N5)/ABS(N5)*100, 0) | Q5: =N5*Product_Data!E5 | R5: =O5*Product_Data!E5
A6: Mamaearth Rosemary Shampoo | B6: =Product_Data!C6 | C6: =Product_Data!F6 | D6: =IF(B6<=300, 0, IF(B6<=500, B6*Parameters!B2, B6*Parameters!B3)) | E6: =IF(B6<=250, 0, Parameters!B4) | F6: =B6*Parameters!B5 | G6: =Product_Data!G6 | H6: =Parameters!B6 | I6: =Parameters!B7 | J6: =Parameters!B8 | K6: =Parameters!B9 | L6: =C6+D6+F6+G6+H6+I6+J6 | M6: =C6+E6+F6+G6+H6+I6+K6 | N6: =B6-L6 | O6: =B6-M6 | P6: =IF(ABS(N6)>0, (O6-N6)/ABS(N6)*100, 0) | Q6: =N6*Product_Data!E6 | R6: =O6*Product_Data!E6
A7: Mamaearth Argan Hair Mask | B7: =Product_Data!C7 | C7: =Product_Data!F7 | D7: =IF(B7<=300, 0, IF(B7<=500, B7*Parameters!B2, B7*Parameters!B3)) | E7: =IF(B7<=250, 0, Parameters!B4) | F7: =B7*Parameters!B5 | G7: =Product_Data!G7 | H7: =Parameters!B6 | I7: =Parameters!B7 | J7: =Parameters!B8 | K7: =Parameters!B9 | L7: =C7+D7+F7+G7+H7+I7+J7 | M7: =C7+E7+F7+G7+H7+I7+K7 | N7: =B7-L7 | O7: =B7-M7 | P7: =IF(ABS(N7)>0, (O7-N7)/ABS(N7)*100, 0) | Q7: =N7*Product_Data!E7 | R7: =O7*Product_Data!E7
A8: Mamaearth Onion Hair Growth Serum (50ml) | B8: =Product_Data!C8 | C8: =Product_Data!F8 | D8: =IF(B8<=300, 0, IF(B8<=500, B8*Parameters!B2, B8*Parameters!B3)) | E8: =IF(B8<=250, 0, Parameters!B4) | F8: =B8*Parameters!B5 | G8: =Product_Data!G8 | H8: =Parameters!B6 | I8: =Parameters!B7 | J8: =Parameters!B8 | K8: =Parameters!B9 | L8: =C8+D8+F8+G8+H8+I8+J8 | M8: =C8+E8+F8+G8+H8+I8+K8 | N8: =B8-L8 | O8: =B8-M8 | P8: =IF(ABS(N8)>0, (O8-N8)/ABS(N8)*100, 0) | Q8: =N8*Product_Data!E8 | R8: =O8*Product_Data!E8
A9: Mamaearth Vitamin C and Turmeric Face Wash | B9: =Product_Data!C9 | C9: =Product_Data!F9 | D9: =IF(B9<=300, 0, IF(B9<=500, B9*Parameters!B2, B9*Parameters!B3)) | E9: =IF(B9<=250, 0, Parameters!B4) | F9: =B9*Parameters!B5 | G9: =Product_Data!G9 | H9: =Parameters!B6 | I9: =Parameters!B7 | J9: =Parameters!B8 | K9: =Parameters!B9 | L9: =C9+D9+F9+G9+H9+I9+J9 | M9: =C9+E9+F9+G9+H9+I9+K9 | N9: =B9-L9 | O9: =B9-M9 | P9: =IF(ABS(N9)>0, (O9-N9)/ABS(N9)*100, 0) | Q9: =N9*Product_Data!E9 | R9: =O9*Product_Data!E9
A10: Ubtan Natural Glow Face Wash with Turmeric & Saffron for Tan Removal – 100 ml | B10: =Product_Data!C10 | C10: =Product_Data!F10 | D10: =IF(B10<=300, 0, IF(B10<=500, B10*Parameters!B2, B10*Parameters!B3)) | E10: =IF(B10<=250, 0, Parameters!B4) | F10: =B10*Parameters!B5 | G10: =Product_Data!G10 | H10: =Parameters!B6 | I10: =Parameters!B7 | J10: =Parameters!B8 | K10: =Parameters!B9 | L10: =C10+D10+F10+G10+H10+I10+J10 | M10: =C10+E10+F10+G10+H10+I10+K10 | N10: =B10-L10 | O10: =B10-M10 | P10: =IF(ABS(N10)>0, (O10-N10)/ABS(N10)*100, 0) | Q10: =N10*Product_Data!E10 | R10: =O10*Product_Data!E10
A11: Tea Tree Pimple Control Face Wash with Tea Tree & Salicylic for Oily & Acne-Prone Skin - 100ml | B11: =Product_Data!C11 | C11: =Product_Data!F11 | D11: =IF(B11<=300, 0, IF(B11<=500, B11*Parameters!B2, B11*Parameters!B3)) | E11: =IF(B11<=250, 0, Parameters!B4) | F11: =B11*Parameters!B5 | G11: =Product_Data!G11 | H11: =Parameters!B6 | I11: =Parameters!B7 | J11: =Parameters!B8 | K11: =Parameters!B9 | L11: =C11+D11+F11+G11+H11+I11+J11 | M11: =C11+E11+F11+G11+H11+I11+K11 | N11: =B11-L11 | O11: =B11-M11 | P11: =IF(ABS(N11)>0, (O11-N11)/ABS(N11)*100, 0) | Q11: =N11*Product_Data!E11 | R11: =O11*Product_Data!E11
A12: Mamaearth Aloe Vera Face Wash | B12: =Product_Data!C12 | C12: =Product_Data!F12 | D12: =IF(B12<=300, 0, IF(B12<=500, B12*Parameters!B2, B12*Parameters!B3)) | E12: =IF(B12<=250, 0, Parameters!B4) | F12: =B12*Parameters!B5 | G12: =Product_Data!G12 | H12: =Parameters!B6 | I12: =Parameters!B7 | J12: =Parameters!B8 | K12: =Parameters!B9 | L12: =C12+D12+F12+G12+H12+I12+J12 | M12: =C12+E12+F12+G12+H12+I12+K12 | N12: =B12-L12 | O12: =B12-M12 | P12: =IF(ABS(N12)>0, (O12-N12)/ABS(N12)*100, 0) | Q12: =N12*Product_Data!E12 | R12: =O12*Product_Data!E12
A13: Rice Dewy Bright Face Wash With Rice Water & Niacinamide for Glass Skin - 200 ml | B13: =Product_Data!C13 | C13: =Product_Data!F13 | D13: =IF(B13<=300, 0, IF(B13<=500, B13*Parameters!B2, B13*Parameters!B3)) | E13: =IF(B13<=250, 0, Parameters!B4) | F13: =B13*Parameters!B5 | G13: =Product_Data!G13 | H13: =Parameters!B6 | I13: =Parameters!B7 | J13: =Parameters!B8 | K13: =Parameters!B9 | L13: =C13+D13+F13+G13+H13+I13+J13 | M13: =C13+E13+F13+G13+H13+I13+K13 | N13: =B13-L13 | O13: =B13-M13 | P13: =IF(ABS(N13)>0, (O13-N13)/ABS(N13)*100, 0) | Q13: =N13*Product_Data!E13 | R13: =O13*Product_Data!E13
A14: Mamaearth Charcoal Face Wash | B14: =Product_Data!C14 | C14: =Product_Data!F14 | D14: =IF(B14<=300, 0, IF(B14<=500, B14*Parameters!B2, B14*Parameters!B3)) | E14: =IF(B14<=250, 0, Parameters!B4) | F14: =B14*Parameters!B5 | G14: =Product_Data!G14 | H14: =Parameters!B6 | I14: =Parameters!B7 | J14: =Parameters!B8 | K14: =Parameters!B9 | L14: =C14+D14+F14+G14+H14+I14+J14 | M14: =C14+E14+F14+G14+H14+I14+K14 | N14: =B14-L14 | O14: =B14-M14 | P14: =IF(ABS(N14)>0, (O14-N14)/ABS(N14)*100, 0) | Q14: =N14*Product_Data!E14 | R14: =O14*Product_Data!E14
A15: Mamaearth Bye Bye Blemishes Face Wash | B15: =Product_Data!C15 | C15: =Product_Data!F15 | D15: =IF(B15<=300, 0, IF(B15<=500, B15*Parameters!B2, B15*Parameters!B3)) | E15: =IF(B15<=250, 0, Parameters!B4) | F15: =B15*Parameters!B5 | G15: =Product_Data!G15 | H15: =Parameters!B6 | I15: =Parameters!B7 | J15: =Parameters!B8 | K15: =Parameters!B9 | L15: =C15+D15+F15+G15+H15+I15+J15 | M15: =C15+E15+F15+G15+H15+I15+K15 | N15: =B15-L15 | O15: =B15-M15 | P15: =IF(ABS(N15)>0, (O15-N15)/ABS(N15)*100, 0) | Q15: =N15*Product_Data!E15 | R15: =O15*Product_Data!E15
A16: Vitamin C Daily Glow Face Cream With Vitamin C & Turmeric for Skin Illumination - 80 g | B16: =Product_Data!C16 | C16: =Product_Data!F16 | D16: =IF(B16<=300, 0, IF(B16<=500, B16*Parameters!B2, B16*Parameters!B3)) | E16: =IF(B16<=250, 0, Parameters!B4) | F16: =B16*Parameters!B5 | G16: =Product_Data!G16 | H16: =Parameters!B6 | I16: =Parameters!B7 | J16: =Parameters!B8 | K16: =Parameters!B9 | L16: =C16+D16+F16+G16+H16+I16+J16 | M16: =C16+E16+F16+G16+H16+I16+K16 | N16: =B16-L16 | O16: =B16-M16 | P16: =IF(ABS(N16)>0, (O16-N16)/ABS(N16)*100, 0) | Q16: =N16*Product_Data!E16 | R16: =O16*Product_Data!E16
A17: Mamaearth Ubtan Natural Glow Face Wash with Turmeric & Saffron for Tan Removal – 150 ml | B17: =Product_Data!C17 | C17: =Product_Data!F17 | D17: =IF(B17<=300, 0, IF(B17<=500, B17*Parameters!B2, B17*Parameters!B3)) | E17: =IF(B17<=250, 0, Parameters!B4) | F17: =B17*Parameters!B5 | G17: =Product_Data!G17 | H17: =Parameters!B6 | I17: =Parameters!B7 | J17: =Parameters!B8 | K17: =Parameters!B9 | L17: =C17+D17+F17+G17+H17+I17+J17 | M17: =C17+E17+F17+G17+H17+I17+K17 | N17: =B17-L17 | O17: =B17-M17 | P17: =IF(ABS(N17)>0, (O17-N17)/ABS(N17)*100, 0) | Q17: =N17*Product_Data!E17 | R17: =O17*Product_Data!E17
A18: Mamaearth Vitamin C Night Cream | B18: =Product_Data!C18 | C18: =Product_Data!F18 | D18: =IF(B18<=300, 0, IF(B18<=500, B18*Parameters!B2, B18*Parameters!B3)) | E18: =IF(B18<=250, 0, Parameters!B4) | F18: =B18*Parameters!B5 | G18: =Product_Data!G18 | H18: =Parameters!B6 | I18: =Parameters!B7 | J18: =Parameters!B8 | K18: =Parameters!B9 | L18: =C18+D18+F18+G18+H18+I18+J18 | M18: =C18+E18+F18+G18+H18+I18+K18 | N18: =B18-L18 | O18: =B18-M18 | P18: =IF(ABS(N18)>0, (O18-N18)/ABS(N18)*100, 0) | Q18: =N18*Product_Data!E18 | R18: =O18*Product_Data!E18
A19: Aqua Glow Face Wash With Himalayan Thermal Water and Hyaluronic Acid for Intense Hydration - 100ml | B19: =Product_Data!C19 | C19: =Product_Data!F19 | D19: =IF(B19<=300, 0, IF(B19<=500, B19*Parameters!B2, B19*Parameters!B3)) | E19: =IF(B19<=250, 0, Parameters!B4) | F19: =B19*Parameters!B5 | G19: =Product_Data!G19 | H19: =Parameters!B6 | I19: =Parameters!B7 | J19: =Parameters!B8 | K19: =Parameters!B9 | L19: =C19+D19+F19+G19+H19+I19+J19 | M19: =C19+E19+F19+G19+H19+I19+K19 | N19: =B19-L19 | O19: =B19-M19 | P19: =IF(ABS(N19)>0, (O19-N19)/ABS(N19)*100, 0) | Q19: =N19*Product_Data!E19 | R19: =O19*Product_Data!E19
A20: Honey Malai Cold Cream with Honey & Malai For Nourishing Glow - 200 g | B20: =Product_Data!C20 | C20: =Product_Data!F20 | D20: =IF(B20<=300, 0, IF(B20<=500, B20*Parameters!B2, B20*Parameters!B3)) | E20: =IF(B20<=250, 0, Parameters!B4) | F20: =B20*Parameters!B5 | G20: =Product_Data!G20 | H20: =Parameters!B6 | I20: =Parameters!B7 | J20: =Parameters!B8 | K20: =Parameters!B9 | L20: =C20+D20+F20+G20+H20+I20+J20 | M20: =C20+E20+F20+G20+H20+I20+K20 | N20: =B20-L20 | O20: =B20-M20 | P20: =IF(ABS(N20)>0, (O20-N20)/ABS(N20)*100, 0) | Q20: =N20*Product_Data!E20 | R20: =O20*Product_Data!E20
A21: Mamaearth Bye Bye Blemishes Face Cream - 30g | B21: =Product_Data!C21 | C21: =Product_Data!F21 | D21: =IF(B21<=300, 0, IF(B21<=500, B21*Parameters!B2, B21*Parameters!B3)) | E21: =IF(B21<=250, 0, Parameters!B4) | F21: =B21*Parameters!B5 | G21: =Product_Data!G21 | H21: =Parameters!B6 | I21: =Parameters!B7 | J21: =Parameters!B8 | K21: =Parameters!B9 | L21: =C21+D21+F21+G21+H21+I21+J21 | M21: =C21+E21+F21+G21+H21+I21+K21 | N21: =B21-L21 | O21: =B21-M21 | P21: =IF(ABS(N21)>0, (O21-N21)/ABS(N21)*100, 0) | Q21: =N21*Product_Data!E21 | R21: =O21*Product_Data!E21
A22: Mamaearth Vitamin C Face Serum | B22: =Product_Data!C22 | C22: =Product_Data!F22 | D22: =IF(B22<=300, 0, IF(B22<=500, B22*Parameters!B2, B22*Parameters!B3)) | E22: =IF(B22<=250, 0, Parameters!B4) | F22: =B22*Parameters!B5 | G22: =Product_Data!G22 | H22: =Parameters!B6 | I22: =Parameters!B7 | J22: =Parameters!B8 | K22: =Parameters!B9 | L22: =C22+D22+F22+G22+H22+I22+J22 | M22: =C22+E22+F22+G22+H22+I22+K22 | N22: =B22-L22 | O22: =B22-M22 | P22: =IF(ABS(N22)>0, (O22-N22)/ABS(N22)*100, 0) | Q22: =N22*Product_Data!E22 | R22: =O22*Product_Data!E22
A23: Mamaearth Niacinamide Face Serum | B23: =Product_Data!C23 | C23: =Product_Data!F23 | D23: =IF(B23<=300, 0, IF(B23<=500, B23*Parameters!B2, B23*Parameters!B3)) | E23: =IF(B23<=250, 0, Parameters!B4) | F23: =B23*Parameters!B5 | G23: =Product_Data!G23 | H23: =Parameters!B6 | I23: =Parameters!B7 | J23: =Parameters!B8 | K23: =Parameters!B9 | L23: =C23+D23+F23+G23+H23+I23+J23 | M23: =C23+E23+F23+G23+H23+I23+K23 | N23: =B23-L23 | O23: =B23-M23 | P23: =IF(ABS(N23)>0, (O23-N23)/ABS(N23)*100, 0) | Q23: =N23*Product_Data!E23 | R23: =O23*Product_Data!E23
A24: Mamaearth Hyaluronic Acid Serum | B24: =Product_Data!C24 | C24: =Product_Data!F24 | D24: =IF(B24<=300, 0, IF(B24<=500, B24*Parameters!B2, B24*Parameters!B3)) | E24: =IF(B24<=250, 0, Parameters!B4) | F24: =B24*Parameters!B5 | G24: =Product_Data!G24 | H24: =Parameters!B6 | I24: =Parameters!B7 | J24: =Parameters!B8 | K24: =Parameters!B9 | L24: =C24+D24+F24+G24+H24+I24+J24 | M24: =C24+E24+F24+G24+H24+I24+K24 | N24: =B24-L24 | O24: =B24-M24 | P24: =IF(ABS(N24)>0, (O24-N24)/ABS(N24)*100, 0) | Q24: =N24*Product_Data!E24 | R24: =O24*Product_Data!E24
A25: Mamaearth Rice Face Scrub | B25: =Product_Data!C25 | C25: =Product_Data!F25 | D25: =IF(B25<=300, 0, IF(B25<=500, B25*Parameters!B2, B25*Parameters!B3)) | E25: =IF(B25<=250, 0, Parameters!B4) | F25: =B25*Parameters!B5 | G25: =Product_Data!G25 | H25: =Parameters!B6 | I25: =Parameters!B7 | J25: =Parameters!B8 | K25: =Parameters!B9 | L25: =C25+D25+F25+G25+H25+I25+J25 | M25: =C25+E25+F25+G25+H25+I25+K25 | N25: =B25-L25 | O25: =B25-M25 | P25: =IF(ABS(N25)>0, (O25-N25)/ABS(N25)*100, 0) | Q25: =N25*Product_Data!E25 | R25: =O25*Product_Data!E25
A26: Mamaearth Ubtan Face Scrub | B26: =Product_Data!C26 | C26: =Product_Data!F26 | D26: =IF(B26<=300, 0, IF(B26<=500, B26*Parameters!B2, B26*Parameters!B3)) | E26: =IF(B26<=250, 0, Parameters!B4) | F26: =B26*Parameters!B5 | G26: =Product_Data!G26 | H26: =Parameters!B6 | I26: =Parameters!B7 | J26: =Parameters!B8 | K26: =Parameters!B9 | L26: =C26+D26+F26+G26+H26+I26+J26 | M26: =C26+E26+F26+G26+H26+I26+K26 | N26: =B26-L26 | O26: =B26-M26 | P26: =IF(ABS(N26)>0, (O26-N26)/ABS(N26)*100, 0) | Q26: =N26*Product_Data!E26 | R26: =O26*Product_Data!E26
A27: Mamaearth Charcoal Face Mask - 200g | B27: =Product_Data!C27 | C27: =Product_Data!F27 | D27: =IF(B27<=300, 0, IF(B27<=500, B27*Parameters!B2, B27*Parameters!B3)) | E27: =IF(B27<=250, 0, Parameters!B4) | F27: =B27*Parameters!B5 | G27: =Product_Data!G27 | H27: =Parameters!B6 | I27: =Parameters!B7 | J27: =Parameters!B8 | K27: =Parameters!B9 | L27: =C27+D27+F27+G27+H27+I27+J27 | M27: =C27+E27+F27+G27+H27+I27+K27 | N27: =B27-L27 | O27: =B27-M27 | P27: =IF(ABS(N27)>0, (O27-N27)/ABS(N27)*100, 0) | Q27: =N27*Product_Data!E27 | R27: =O27*Product_Data!E27
A28: Vitamin C Daily Glow Face Serum - 10ml | B28: =Product_Data!C28 | C28: =Product_Data!F28 | D28: =IF(B28<=300, 0, IF(B28<=500, B28*Parameters!B2, B28*Parameters!B3)) | E28: =IF(B28<=250, 0, Parameters!B4) | F28: =B28*Parameters!B5 | G28: =Product_Data!G28 | H28: =Parameters!B6 | I28: =Parameters!B7 | J28: =Parameters!B8 | K28: =Parameters!B9 | L28: =C28+D28+F28+G28+H28+I28+J28 | M28: =C28+E28+F28+G28+H28+I28+K28 | N28: =B28-L28 | O28: =B28-M28 | P28: =IF(ABS(N28)>0, (O28-N28)/ABS(N28)*100, 0) | Q28: =N28*Product_Data!E28 | R28: =O28*Product_Data!E28
A29: Mamaearth Vitamin C Body Lotion | B29: =Product_Data!C29 | C29: =Product_Data!F29 | D29: =IF(B29<=300, 0, IF(B29<=500, B29*Parameters!B2, B29*Parameters!B3)) | E29: =IF(B29<=250, 0, Parameters!B4) | F29: =B29*Parameters!B5 | G29: =Product_Data!G29 | H29: =Parameters!B6 | I29: =Parameters!B7 | J29: =Parameters!B8 | K29: =Parameters!B9 | L29: =C29+D29+F29+G29+H29+I29+J29 | M29: =C29+E29+F29+G29+H29+I29+K29 | N29: =B29-L29 | O29: =B29-M29 | P29: =IF(ABS(N29)>0, (O29-N29)/ABS(N29)*100, 0) | Q29: =N29*Product_Data!E29 | R29: =O29*Product_Data!E29
A30: Mamaearth Ubtan Body Lotion | B30: =Product_Data!C30 | C30: =Product_Data!F30 | D30: =IF(B30<=300, 0, IF(B30<=500, B30*Parameters!B2, B30*Parameters!B3)) | E30: =IF(B30<=250, 0, Parameters!B4) | F30: =B30*Parameters!B5 | G30: =Product_Data!G30 | H30: =Parameters!B6 | I30: =Parameters!B7 | J30: =Parameters!B8 | K30: =Parameters!B9 | L30: =C30+D30+F30+G30+H30+I30+J30 | M30: =C30+E30+F30+G30+H30+I30+K30 | N30: =B30-L30 | O30: =B30-M30 | P30: =IF(ABS(N30)>0, (O30-N30)/ABS(N30)*100, 0) | Q30: =N30*Product_Data!E30 | R30: =O30*Product_Data!E30
A31: Mamaearth Cocoa Rich Moisturizing Body Lotion with Cocoa Butter & Vitamin E for Intense Moisturization - 400 ml | B31: =Product_Data!C31 | C31: =Product_Data!F31 | D31: =IF(B31<=300, 0, IF(B31<=500, B31*Parameters!B2, B31*Parameters!B3)) | E31: =IF(B31<=250, 0, Parameters!B4) | F31: =B31*Parameters!B5 | G31: =Product_Data!G31 | H31: =Parameters!B6 | I31: =Parameters!B7 | J31: =Parameters!B8 | K31: =Parameters!B9 | L31: =C31+D31+F31+G31+H31+I31+J31 | M31: =C31+E31+F31+G31+H31+I31+K31 | N31: =B31-L31 | O31: =B31-M31 | P31: =IF(ABS(N31)>0, (O31-N31)/ABS(N31)*100, 0) | Q31: =N31*Product_Data!E31 | R31: =O31*Product_Data!E31
A32: Mamaearth Tea Tree Body Wash With Tea Tree and Neem For Skin Purification - 300 ml | B32: =Product_Data!C32 | C32: =Product_Data!F32 | D32: =IF(B32<=300, 0, IF(B32<=500, B32*Parameters!B2, B32*Parameters!B3)) | E32: =IF(B32<=250, 0, Parameters!B4) | F32: =B32*Parameters!B5 | G32: =Product_Data!G32 | H32: =Parameters!B6 | I32: =Parameters!B7 | J32: =Parameters!B8 | K32: =Parameters!B9 | L32: =C32+D32+F32+G32+H32+I32+J32 | M32: =C32+E32+F32+G32+H32+I32+K32 | N32: =B32-L32 | O32: =B32-M32 | P32: =IF(ABS(N32)>0, (O32-N32)/ABS(N32)*100, 0) | Q32: =N32*Product_Data!E32 | R32: =O32*Product_Data!E32
A33: Milky Soft Shampoo with Oats, Milk and Calendula for Babies - 400 ml | B33: =Product_Data!C33 | C33: =Product_Data!F33 | D33: =IF(B33<=300, 0, IF(B33<=500, B33*Parameters!B2, B33*Parameters!B3)) | E33: =IF(B33<=250, 0, Parameters!B4) | F33: =B33*Parameters!B5 | G33: =Product_Data!G33 | H33: =Parameters!B6 | I33: =Parameters!B7 | J33: =Parameters!B8 | K33: =Parameters!B9 | L33: =C33+D33+F33+G33+H33+I33+J33 | M33: =C33+E33+F33+G33+H33+I33+K33 | N33: =B33-L33 | O33: =B33-M33 | P33: =IF(ABS(N33)>0, (O33-N33)/ABS(N33)*100, 0) | Q33: =N33*Product_Data!E33 | R33: =O33*Product_Data!E33
A34: Milky Soft Body Lotion for Babies with Oats, Milk & Calendula – 200ml | B34: =Product_Data!C34 | C34: =Product_Data!F34 | D34: =IF(B34<=300, 0, IF(B34<=500, B34*Parameters!B2, B34*Parameters!B3)) | E34: =IF(B34<=250, 0, Parameters!B4) | F34: =B34*Parameters!B5 | G34: =Product_Data!G34 | H34: =Parameters!B6 | I34: =Parameters!B7 | J34: =Parameters!B8 | K34: =Parameters!B9 | L34: =C34+D34+F34+G34+H34+I34+J34 | M34: =C34+E34+F34+G34+H34+I34+K34 | N34: =B34-L34 | O34: =B34-M34 | P34: =IF(ABS(N34)>0, (O34-N34)/ABS(N34)*100, 0) | Q34: =N34*Product_Data!E34 | R34: =O34*Product_Data!E34
A35: Moisturizing Bathing Bar Soap For Babies, pack of 2*75g | B35: =Product_Data!C35 | C35: =Product_Data!F35 | D35: =IF(B35<=300, 0, IF(B35<=500, B35*Parameters!B2, B35*Parameters!B3)) | E35: =IF(B35<=250, 0, Parameters!B4) | F35: =B35*Parameters!B5 | G35: =Product_Data!G35 | H35: =Parameters!B6 | I35: =Parameters!B7 | J35: =Parameters!B8 | K35: =Parameters!B9 | L35: =C35+D35+F35+G35+H35+I35+J35 | M35: =C35+E35+F35+G35+H35+I35+K35 | N35: =B35-L35 | O35: =B35-M35 | P35: =IF(ABS(N35)>0, (O35-N35)/ABS(N35)*100, 0) | Q35: =N35*Product_Data!E35 | R35: =O35*Product_Data!E35
A36: Mamaearth Lip Balm | B36: =Product_Data!C36 | C36: =Product_Data!F36 | D36: =IF(B36<=300, 0, IF(B36<=500, B36*Parameters!B2, B36*Parameters!B3)) | E36: =IF(B36<=250, 0, Parameters!B4) | F36: =B36*Parameters!B5 | G36: =Product_Data!G36 | H36: =Parameters!B6 | I36: =Parameters!B7 | J36: =Parameters!B8 | K36: =Parameters!B9 | L36: =C36+D36+F36+G36+H36+I36+J36 | M36: =C36+E36+F36+G36+H36+I36+K36 | N36: =B36-L36 | O36: =B36-M36 | P36: =IF(ABS(N36)>0, (O36-N36)/ABS(N36)*100, 0) | Q36: =N36*Product_Data!E36 | R36: =O36*Product_Data!E36
A37: Mamaearth Tinted Lip Balm | B37: =Product_Data!C37 | C37: =Product_Data!F37 | D37: =IF(B37<=300, 0, IF(B37<=500, B37*Parameters!B2, B37*Parameters!B3)) | E37: =IF(B37<=250, 0, Parameters!B4) | F37: =B37*Parameters!B5 | G37: =Product_Data!G37 | H37: =Parameters!B6 | I37: =Parameters!B7 | J37: =Parameters!B8 | K37: =Parameters!B9 | L37: =C37+D37+F37+G37+H37+I37+J37 | M37: =C37+E37+F37+G37+H37+I37+K37 | N37: =B37-L37 | O37: =B37-M37 | P37: =IF(ABS(N37)>0, (O37-N37)/ABS(N37)*100, 0) | Q37: =N37*Product_Data!E37 | R37: =O37*Product_Data!E37
A38: Mamaearth Under Eye Cream | B38: =Product_Data!C38 | C38: =Product_Data!F38 | D38: =IF(B38<=300, 0, IF(B38<=500, B38*Parameters!B2, B38*Parameters!B3)) | E38: =IF(B38<=250, 0, Parameters!B4) | F38: =B38*Parameters!B5 | G38: =Product_Data!G38 | H38: =Parameters!B6 | I38: =Parameters!B7 | J38: =Parameters!B8 | K38: =Parameters!B9 | L38: =C38+D38+F38+G38+H38+I38+J38 | M38: =C38+E38+F38+G38+H38+I38+K38 | N38: =B38-L38 | O38: =B38-M38 | P38: =IF(ABS(N38)>0, (O38-N38)/ABS(N38)*100, 0) | Q38: =N38*Product_Data!E38 | R38: =O38*Product_Data!E38
A39: Charcoal Black Long Stay Kajal with Vitamin C & Chamomile for 11-Hour Smudge-free Stay | B39: =Product_Data!C39 | C39: =Product_Data!F39 | D39: =IF(B39<=300, 0, IF(B39<=500, B39*Parameters!B2, B39*Parameters!B3)) | E39: =IF(B39<=250, 0, Parameters!B4) | F39: =B39*Parameters!B5 | G39: =Product_Data!G39 | H39: =Parameters!B6 | I39: =Parameters!B7 | J39: =Parameters!B8 | K39: =Parameters!B9 | L39: =C39+D39+F39+G39+H39+I39+J39 | M39: =C39+E39+F39+G39+H39+I39+K39 | N39: =B39-L39 | O39: =B39-M39 | P39: =IF(ABS(N39)>0, (O39-N39)/ABS(N39)*100, 0) | Q39: =N39*Product_Data!E39 | R39: =O39*Product_Data!E39

Sheet Scenario_Analysis
A1: Scenario Parameter Changes (%):
A2: CAC Amazon % Change | B2: 0
A3: CAC ONDC % Change | B3: 0
A4: Logistics % Change | B4: 0
A5: ONDC Commission % Change | B5: 0
A6: Note: Profit_Change_vs_Base shows 0% because all scenario parameters are set to 0% change (no adjustments). To see changes, enter percentage values in cells B2-B5 above (e.g., 10% = 0.10, -5% = -0.05).
A7: Product_Name | B7: Base_Profit_ONDC | C7: Adjusted_CAC_ONDC | D7: Adjusted_Logistics | E7: Adjusted_ONDC_Comm | F7: Adjusted_Total_Cost_ONDC | G7: Adjusted_Profit_ONDC | H7: Profit_Change_vs_Base
A8: Mamaearth Onion Hair Oil | B8: =Unit_Economics!O2 | C8: =Parameters!B9*(1+B3) | D8: =Unit_Economics!G2*(1+B4) | E8: =IF(Unit_Economics!B2<=250, 0, Parameters!B4*(1+B5)) | F8: =Unit_Economics!C2+E8+Unit_Economics!F2+D8+C8+Parameters!B6+Parameters!B7 | G8: =Unit_Economics!B2-F8 | H8: =IF(ABS(B8)>0, (G8-B8)/ABS(B8)*100, 0)
A9: Mamaearth Onion Shampoo | B9: =Unit_Economics!O3 | C9: =Parameters!B9*(1+B3) | D9: =Unit_Economics!G3*(1+B4) | E9: =IF(Unit_Economics!B3<=250, 0, Parameters!B4*(1+B5)) | F9: =Unit_Economics!C3+E9+Unit_Economics!F3+D9+C9+Parameters!B6+Parameters!B7 | G9: =Unit_Economics!B3-F9 | H9: =IF(ABS(B9)>0, (G9-B9)/ABS(B9)*100, 0)
A10: Mamaearth Onion Conditioner | B10: =Unit_Economics!O4 | C10: =Parameters!B9*(1+B3) | D10: =Unit_Economics!G4*(1+B4) | E10: =IF(Unit_Economics!B4<=250, 0, Parameters!B4*(1+B5)) | F10: =Unit_Economics!C4+E10+Unit_Economics!F4+D10+C10+Parameters!B6+Parameters!B7 | G10: =Unit_Economics!B4-F10 | H10: =IF(ABS(B10)>0, (G10-B10)/ABS(B10)*100, 0)
A11: Rosemary Hair Growth Oil with Rosemary & Methi Dana for Promoting Hair Growth - 100 ml | B11: =Unit_Economics!O5 | C11: =Parameters!B9*(1+B3) | D11: =Unit_Economics!G5*(1+B4) | E11: =IF(Unit_Economics!B5<=250, 0, Parameters!B4*(1+B5)) | F11: =Unit_Economics!C5+E11+Unit_Economics!F5+D11+C11+Parameters!B6+Parameters!B7 | G11: =Unit_Economics!B5-F11 | H11: =IF(ABS(B11)>0, (G11-B11)/ABS(B11)*100, 0)
A12: Mamaearth Rosemary Shampoo | B12: =Unit_Economics!O6 | C12: =Parameters!B9*(1+B3) | D12: =Unit_Economics!G6*(1+B4) | E12: =IF(Unit_Economics!B6<=250, 0, Parameters!B4*(1+B5)) | F12: =Unit_Economics!C6+E12+Unit_Economics!F6+D12+C12+Parameters!B6+Parameters!B7 | G12: =Unit_Economics!B6-F12 | H12: =IF(ABS(B12)>0, (G12-B12)/ABS(B12)*100, 0)
A13: Mamaearth Argan Hair Mask | B13: =Unit_Economics!O7 | C13: =Parameters!B9*(1+B3) | D13: =Unit_Economics!G7*(1+B4) | E13: =IF(Unit_Economics!B7<=250, 0, Parameters!B4*(1+B5)) | F13: =Unit_Economics!C7+E13+Unit_Economics!F7+D13+C13+Parameters!B6+Parameters!B7 | G13: =Unit_Economics!B7-F13 | H13: =IF(ABS(B13)>0, (G13-B13)/ABS(B13)*100, 0)
A14: Mamaearth Onion Hair Growth Serum (50ml) | B14: =Unit_Economics!O8 | C14: =Parameters!B9*(1+B3) | D14: =Unit_Economics!G8*(1+B4) | E14: =IF(Unit_Economics!B8<=250, 0, Parameters!B4*(1+B5)) | F14: =Unit_Economics!C8+E14+Unit_Economics!F8+D14+C14+Parameters!B6+Parameters!B7 | G14: =Unit_Economics!B8-F14 | H14: =IF(ABS(B14)>0, (G14-B14)/ABS(B14)*100, 0)
A15: Mamaearth Vitamin C and Turmeric Face Wash | B15: =Unit_Economics!O9 | C15: =Parameters!B9*(1+B3) | D15: =Unit_Economics!G9*(1+B4) | E15: =IF(Unit_Economics!B9<=250, 0, Parameters!B4*(1+B5)) | F15: =Unit_Economics!C9+E15+Unit_Economics!F9+D15+C15+Parameters!B6+Parameters!B7 | G15: =Unit_Economics!B9-F15 | H15: =IF(ABS(B15)>0, (G15-B15)/ABS(B15)*100, 0)
A16: Ubtan Natural Glow Face Wash with Turmeric & Saffron for Tan Removal – 100 ml | B16: =Unit_Economics!O10 | C16: =Parameters!B9*(1+B3) | D16: =Unit_Economics!G10*(1+B4) | E16: =IF(Unit_Economics!B10<=250, 0, Parameters!B4*(1+B5)) | F16: =Unit_Economics!C10+E16+Unit_Economics!F10+D16+C16+Parameters!B6+Parameters!B7 | G16: =Unit_Economics!B10-F16 | H16: =IF(ABS(B16)>0, (G16-B16)/ABS(B16)*100, 0)
A17: Tea Tree Pimple Control Face Wash with Tea Tree & Salicylic for Oily & Acne-Prone Skin - 100ml | B17: =Unit_Economics!O11 | C17: =Parameters!B9*(1+B3) | D17: =Unit_Economics!G11*(1+B4) | E17: =IF(Unit_Economics!B11<=250, 0, Parameters!B4*(1+B5)) | F17: =Unit_Economics!C11+E17+Unit_Economics!F11+D17+C17+Parameters!B6+Parameters!B7 | G17: =Unit_Economics!B11-F17 | H17: =IF(ABS(B17)>0, (G17-B17)/ABS(B17)*100, 0)
A18: Mamaearth Aloe Vera Face Wash | B18: =Unit_Economics!O12 | C18: =Parameters!B9*(1+B3) | D18: =Unit_Economics!G12*(1+B4) | E18: =IF(Unit_Economics!B12<=250, 0, Parameters!B4*(1+B5)) | F18: =Unit_Economics!C12+E18+Unit_Economics!F12+D18+C18+Parameters!B6+Parameters!B7 | G18: =Unit_Economics!B12-F18 | H18: =IF(ABS(B18)>0, (G18-B18)/ABS(B18)*100, 0)
A19: Rice Dewy Bright Face Wash With Rice Water & Niacinamide for Glass Skin - 200 ml | B19: =Unit_Economics!O13 | C19: =Parameters!B9*(1+B3) | D19: =Unit_Economics!G13*(1+B4) | E19: =IF(Unit_Economics!B13<=250, 0, Parameters!B4*(1+B5)) | F19: =Unit_Economics!C13+E19+Unit_Economics!F13+D19+C19+Parameters!B6+Parameters!B7 | G19: =Unit_Economics!B13-F19 | H19: =IF(ABS(B19)>0, (G19-B19)/ABS(B19)*100, 0)
A20: Mamaearth Charcoal Face Wash | B20: =Unit_Economics!O14 | C20: =Parameters!B9*(1+B3) | D20: =Unit_Economics!G14*(1+B4) | E20: =IF(Unit_Economics!B14<=250, 0, Parameters!B4*(1+B5)) | F20: =Unit_Economics!C14+E20+Unit_Economics!F14+D20+C20+Parameters!B6+Parameters!B7 | G20: =Unit_Economics!B14-F20 | H20: =IF(ABS(B20)>0, (G20-B20)/ABS(B20)*100, 0)
A21: Mamaearth Bye Bye Blemishes Face Wash | B21: =Unit_Economics!O15 | C21: =Parameters!B9*(1+B3) | D21: =Unit_Economics!G15*(1+B4) | E21: =IF(Unit_Economics!B15<=250, 0, Parameters!B4*(1+B5)) | F21: =Unit_Economics!C15+E21+Unit_Economics!F15+D21+C21+Parameters!B6+Parameters!B7 | G21: =Unit_Economics!B15-F21 | H21: =IF(ABS(B21)>0, (G21-B21)/ABS(B21)*100, 0)
A22: Vitamin C Daily Glow Face Cream With Vitamin C & Turmeric for Skin Illumination - 80 g | B22: =Unit_Economics!O16 | C22: =Parameters!B9*(1+B3) | D22: =Unit_Economics!G16*(1+B4) | E22: =IF(Unit_Economics!B16<=250, 0, Parameters!B4*(1+B5)) | F22: =Unit_Economics!C16+E22+Unit_Economics!F16+D22+C22+Parameters!B6+Parameters!B7 | G22: =Unit_Economics!B16-F22 | H22: =IF(ABS(B22)>0, (G22-B22)/ABS(B22)*100, 0)
A23: Mamaearth Ubtan Natural Glow Face Wash with Turmeric & Saffron for Tan Removal – 150 ml | B23: =Unit_Economics!O17 | C23: =Parameters!B9*(1+B3) | D23: =Unit_Economics!G17*(1+B4) | E23: =IF(Unit_Economics!B17<=250, 0, Parameters!B4*(1+B5)) | F23: =Unit_Economics!C17+E23+Unit_Economics!F17+D23+C23+Parameters!B6+Parameters!B7 | G23: =Unit_Economics!B17-F23 | H23: =IF(ABS(B23)>0, (G23-B23)/ABS(B23)*100, 0)
A24: Mamaearth Vitamin C Night Cream | B24: =Unit_Economics!O18 | C24: =Parameters!B9*(1+B3) | D24: =Unit_Economics!G18*(1+B4) | E24: =IF(Unit_Economics!B18<=250, 0, Parameters!B4*(1+B5)) | F24: =Unit_Economics!C18+E24+Unit_Economics!F18+D24+C24+Parameters!B6+Parameters!B7 | G24: =Unit_Economics!B18-F24 | H24: =IF(ABS(B24)>0, (G24-B24)/ABS(B24)*100, 0)
A25: Aqua Glow Face Wash With Himalayan Thermal Water and Hyaluronic Acid for Intense Hydration - 100ml | B25: =Unit_Economics!O19 | C25: =Parameters!B9*(1+B3) | D25: =Unit_Economics!G19*(1+B4) | E25: =IF(Unit_Economics!B19<=250, 0, Parameters!B4*(1+B5)) | F25: =Unit_Economics!C19+E25+Unit_Economics!F19+D25+C25+Parameters!B6+Parameters!B7 | G25: =Unit_Economics!B19-F25 | H25: =IF(ABS(B25)>0, (G25-B25)/ABS(B25)*100, 0)
A26: Honey Malai Cold Cream with Honey & Malai For Nourishing Glow - 200 g | B26: =Unit_Economics!O20 | C26: =Parameters!B9*(1+B3) | D26: =Unit_Economics!G20*(1+B4) | E26: =IF(Unit_Economics!B20<=250, 0, Parameters!B4*(1+B5)) | F26: =Unit_Economics!C20+E26+Unit_Economics!F20+D26+C26+Parameters!B6+Parameters!B7 | G26: =Unit_Economics!B20-F26 | H26: =IF(ABS(B26)>0, (G26-B26)/ABS(B26)*100, 0)
A27: Mamaearth Bye Bye Blemishes Face Cream - 30g | B27: =Unit_Economics!O21 | C27: =Parameters!B9*(1+B3) | D27: =Unit_Economics!G21*(1+B4) | E27: =IF(Unit_Economics!B21<=250, 0, Parameters!B4*(1+B5)) | F27: =Unit_Economics!C21+E27+Unit_Economics!F21+D27+C27+Parameters!B6+Parameters!B7 | G27: =Unit_Economics!B21-F27 | H27: =IF(ABS(B27)>0, (G27-B27)/ABS(B27)*100, 0)
A28: Mamaearth Vitamin C Face Serum | B28: =Unit_Economics!O22 | C28: =Parameters!B9*(1+B3) | D28: =Unit_Economics!G22*(1+B4) | E28: =IF(Unit_Economics!B22<=250, 0, Parameters!B4*(1+B5)) | F28: =Unit_Economics!C22+E28+Unit_Economics!F22+D28+C28+Parameters!B6+Parameters!B7 | G28: =Unit_Economics!B22-F28 | H28: =IF(ABS(B28)>0, (G28-B28)/ABS(B28)*100, 0)
A29: Mamaearth Niacinamide Face Serum | B29: =Unit_Economics!O23 | C29: =Parameters!B9*(1+B3) | D29: =Unit_Economics!G23*(1+B4) | E29: =IF(Unit_Economics!B23<=250, 0, Parameters!B4*(1+B5)) | F29: =Unit_Economics!C23+E29+Unit_Economics!F23+D29+C29+Parameters!B6+Parameters!B7 | G29: =Unit_Economics!B23-F29 | H29: =IF(ABS(B29)>0, (G29-B29)/ABS(B29)*100, 0)
A30: Mamaearth Hyaluronic Acid Serum | B30: =Unit_Economics!O24 | C30: =Parameters!B9*(1+B3) | D30: =Unit_Economics!G24*(1+B4) | E30: =IF(Unit_Economics!B24<=250, 0, Parameters!B4*(1+B5)) | F30: =Unit_Economics!C24+E30+Unit_Economics!F24+D30+C30+Parameters!B6+Parameters!B7 | G30: =Unit_Economics!B24-F30 | H30: =IF(ABS(B30)>0, (G30-B30)/ABS(B30)*100, 0)
A31: Mamaearth Rice Face Scrub | B31: =Unit_Economics!O25 | C31: =Parameters!B9*(1+B3) | D31: =Unit_Economics!G25*(1+B4) | E31: =IF(Unit_Economics!B25<=250, 0, Parameters!B4*(1+B5)) | F31: =Unit_Economics!C25+E31+Unit_Economics!F25+D31+C31+Parameters!B6+Parameters!B7 | G31: =Unit_Economics!B25-F31 | H31: =IF(ABS(B31)>0, (G31-B31)/ABS(B31)*100, 0)
A32: Mamaearth Ubtan Face Scrub | B32: =Unit_Economics!O26 | C32: =Parameters!B9*(1+B3) | D32: =Unit_Economics!G26*(1+B4) | E32: =IF(Unit_Economics!B26<=250, 0, Parameters!B4*(1+B5)) | F32: =Unit_Economics!C26+E32+Unit_Economics!F26+D32+C32+Parameters!B6+Parameters!B7 | G32: =Unit_Economics!B26-F32 | H32: =IF(ABS(B32)>0, (G32-B32)/ABS(B32)*100, 0)
A33: Mamaearth Charcoal Face Mask - 200g | B33: =Unit_Economics!O27 | C33: =Parameters!B9*(1+B3) | D33: =Unit_Economics!G27*(1+B4) | E33: =IF(Unit_Economics!B27<=250, 0, Parameters!B4*(1+B5)) | F33: =Unit_Economics!C27+E33+Unit_Economics!F27+D33+C33+Parameters!B6+Parameters!B7 | G33: =Unit_Economics!B27-F33 | H33: =IF(ABS(B33)>0, (G33-B33)/ABS(B33)*100, 0)
A34: Vitamin C Daily Glow Face Serum - 10ml | B34: =Unit_Economics!O28 | C34: =Parameters!B9*(1+B3) | D34: =Unit_Economics!G28*(1+B4) | E34: =IF(Unit_Economics!B28<=250, 0, Parameters!B4*(1+B5)) | F34: =Unit_Economics!C28+E34+Unit_Economics!F28+D34+C34+Parameters!B6+Parameters!B7 | G34: =Unit_Economics!B28-F34 | H34: =IF(ABS(B34)>0, (G34-B34)/ABS(B34)*100, 0)
A35: Mamaearth Vitamin C Body Lotion | B35: =Unit_Economics!O29 | C35: =Parameters!B9*(1+B3) | D35: =Unit_Economics!G29*(1+B4) | E35: =IF(Unit_Economics!B29<=250, 0, Parameters!B4*(1+B5)) | F35: =Unit_Economics!C29+E35+Unit_Economics!F29+D35+C35+Parameters!B6+Parameters!B7 | G35: =Unit_Economics!B29-F35 | H35: =IF(ABS(B35)>0, (G35-B35)/ABS(B35)*100, 0)
A36: Mamaearth Ubtan Body Lotion | B36: =Unit_Economics!O30 | C36: =Parameters!B9*(1+B3) | D36: =Unit_Economics!G30*(1+B4) | E36: =IF(Unit_Economics!B30<=250, 0, Parameters!B4*(1+B5)) | F36: =Unit_Economics!C30+E36+Unit_Economics!F30+D36+C36+Parameters!B6+Parameters!B7 | G36: =Unit_Economics!B30-F36 | H36: =IF(ABS(B36)>0, (G36-B36)/ABS(B36)*100, 0)
A37: Mamaearth Cocoa Rich Moisturizing Body Lotion with Cocoa Butter & Vitamin E for Intense Moisturization - 400 ml | B37: =Unit_Economics!O31 | C37: =Parameters!B9*(1+B3) | D37: =Unit_Economics!G31*(1+B4) | E37: =IF(Unit_Economics!B31<=250, 0, Parameters!B4*(1+B5)) | F37: =Unit_Economics!C31+E37+Unit_Economics!F31+D37+C37+Parameters!B6+Parameters!B7 | G37: =Unit_Economics!B31-F37 | H37: =IF(ABS(B37)>0, (G37-B37)/ABS(B37)*100, 0)
A38: Mamaearth Tea Tree Body Wash With Tea Tree and Neem For Skin Purification - 300 ml | B38: =Unit_Economics!O32 | C38: =Parameters!B9*(1+B3) | D38: =Unit_Economics!G32*(1+B4) | E38: =IF(Unit_Economics!B32<=250, 0, Parameters!B4*(1+B5)) | F38: =Unit_Economics!C32+E38+Unit_Economics!F32+D38+C38+Parameters!B6+Parameters!B7 | G38: =Unit_Economics!B32-F38 | H38: =IF(ABS(B38)>0, (G38-B38)/ABS(B38)*100, 0)
A39: Milky Soft Shampoo with Oats, Milk and Calendula for Babies - 400 ml | B39: =Unit_Economics!O33 | C39: =Parameters!B9*(1+B3) | D39: =Unit_Economics!G33*(1+B4) | E39: =IF(Unit_Economics!B33<=250, 0, Parameters!B4*(1+B5)) | F39: =Unit_Economics!C33+E39+Unit_Economics!F33+D39+C39+Parameters!B6+Parameters!B7 | G39: =Unit_Economics!B33-F39 | H39: =IF(ABS(B39)>0, (G39-B39)/ABS(B39)*100, 0)
A40: Milky Soft Body Lotion for Babies with Oats, Milk & Calendula – 200ml | B40: =Unit_Economics!O34 | C40: =Parameters!B9*(1+B3) | D40: =Unit_Economics!G34*(1+B4) | E40: =IF(Unit_Economics!B34<=250, 0, Parameters!B4*(1+B5)) | F40: =Unit_Economics!C34+E40+Unit_Economics!F34+D40+C40+Parameters!B6+Parameters!B7 | G40: =Unit_Economics!B34-F40 | H40: =IF(ABS(B40)>0, (G40-B40)/ABS(B40)*100, 0)
...

Sheet Break_Even
A1: Fixed Costs (Monthly): | B1: =Parameters!B10
A3: Product_Name | B3: Selling_Price | C3: Total_Variable_Cost_ONDC | D3: Contribution_per_unit_ONDC | E3: Break_even_units | F3: Break_even_revenue
A4: Mamaearth Onion Hair Oil | B4: =Unit_Economics!B4 | C4: =Unit_Economics!M4 | D4: =B4-C4 | E4: =IF(D4>0, B1/D4, 0) | F4: =E4*B4
A5: Mamaearth Onion Shampoo | B5: =Unit_Economics!B5 | C5: =Unit_Economics!M5 | D5: =B5-C5 | E5: =IF(D5>0, B1/D5, 0) | F5: =E5*B5
A6: Mamaearth Onion Conditioner | B6: =Unit_Economics!B6 | C6: =Unit_Economics!M6 | D6: =B6-C6 | E6: =IF(D6>0, B1/D6, 0) | F6: =E6*B6
A7: Rosemary Hair Growth Oil with Rosemary & Methi Dana for Promoting Hair Growth - 100 ml | B7: =Unit_Economics!B7 | C7: =Unit_Economics!M7 | D7: =B7-C7 | E7: =IF(D7>0, B1/D7, 0) | F7: =E7*B7
A8: Mamaearth Rosemary Shampoo | B8: =Unit_Economics!B8 | C8: =Unit_Economics!M8 | D8: =B8-C8 | E8: =IF(D8>0, B1/D8, 0) | F8: =E8*B8
A9: Mamaearth Argan Hair Mask | B9: =Unit_Economics!B9 | C9: =Unit_Economics!M9 | D9: =B9-C9 | E9: =IF(D9>0, B1/D9, 0) | F9: =E9*B9
A10: Mamaearth Onion Hair Growth Serum (50ml) | B10: =Unit_Economics!B10 | C10: =Unit_Economics!M10 | D10: =B10-C10 | E10: =IF(D10>0, B1/D10, 0) | F10: =E10*B10
A11: Mamaearth Vitamin C and Turmeric Face Wash | B11: =Unit_Economics!B11 | C11: =Unit_Economics!M11 | D11: =B11-C11 | E11: =IF(D11>0, B1/D11, 0) | F11: =E11*B11
A12: Ubtan Natural Glow Face Wash with Turmeric & Saffron for Tan Removal – 100 ml | B12: =Unit_Economics!B12 | C12: =Unit_Economics!M12 | D12: =B12-C12 | E12: =IF(D12>0, B1/D12, 0) | F12: =E12*B12
A13: Tea Tree Pimple Control Face Wash with Tea Tree & Salicylic for Oily & Acne-Prone Skin - 100ml | B13: =Unit_Economics!B13 | C13: =Unit_Economics!M13 | D13: =B13-C13 | E13: =IF(D13>0, B1/D13, 0) | F13: =E13*B13
A14: Mamaearth Aloe Vera Face Wash | B14: =Unit_Economics!B14 | C14: =Unit_Economics!M14 | D14: =B14-C14 | E14: =IF(D14>0, B1/D14, 0) | F14: =E14*B14
A15: Rice Dewy Bright Face Wash With Rice Water & Niacinamide for Glass Skin - 200 ml | B15: =Unit_Economics!B15 | C15: =Unit_Economics!M15 | D15: =B15-C15 | E15: =IF(D15>0, B1/D15, 0) | F15: =E15*B15
A16: Mamaearth Charcoal Face Wash | B16: =Unit_Economics!B16 | C16: =Unit_Economics!M16 | D16: =B16-C16 | E16: =IF(D16>0, B1/D16, 0) | F16: =E16*B16
A17: Mamaearth Bye Bye Blemishes Face Wash | B17: =Unit_Economics!B17 | C17: =Unit_Economics!M17 | D17: =B17-C17 | E17: =IF(D17>0, B1/D17, 0) | F17: =E17*B17
A18: Vitamin C Daily Glow Face Cream With Vitamin C & Turmeric for Skin Illumination - 80 g | B18: =Unit_Economics!B18 | C18: =Unit_Economics!M18 | D18: =B18-C18 | E18: =IF(D18>0, B1/D18, 0) | F18: =E18*B18
A19: Mamaearth Ubtan Natural Glow Face Wash with Turmeric & Saffron for Tan Removal – 150 ml | B19: =Unit_Economics!B19 | C19: =Unit_Economics!M19 | D19: =B19-C19 | E19: =IF(D19>0, B1/D19, 0) | F19: =E19*B19
A20: Mamaearth Vitamin C Night Cream | B20: =Unit_Economics!B20 | C20: =Unit_Economics!M20 | D20: =B20-C20 | E20: =IF(D20>0, B1/D20, 0) | F20: =E20*B20
A21: Aqua Glow Face Wash With Himalayan Thermal Water and Hyaluronic Acid for Intense Hydration - 100ml | B21: =Unit_Economics!B21 | C21: =Unit_Economics!M21 | D21: =B21-C21 | E21: =IF(D21>0, B1/D21, 0) | F21: =E21*B21
A22: Honey Malai Cold Cream with Honey & Malai For Nourishing Glow - 200 g | B22: =Unit_Economics!B22 | C22: =Unit_Economics!M22 | D22: =B22-C22 | E22: =IF(D22>0, B1/D22, 0) | F22: =E22*B22
A23: Mamaearth Bye Bye Blemishes Face Cream - 30g | B23: =Unit_Economics!B23 | C23: =Unit_Economics!M23 | D23: =B23-C23 | E23: =IF(D23>0, B1/D23, 0) | F23: =E23*B23
A24: Mamaearth Vitamin C Face Serum | B24: =Unit_Economics!B24 | C24: =Unit_Economics!M24 | D24: =B24-C24 | E24: =IF(D24>0, B1/D24, 0) | F24: =E24*B24
A25: Mamaearth Niacinamide Face Serum | B25: =Unit_Economics!B25 | C25: =Unit_Economics!M25 | D25: =B25-C25 | E25: =IF(D25>0, B1/D25, 0) | F25: =E25*B25
A26: Mamaearth Hyaluronic Acid Serum | B26: =Unit_Economics!B26 | C26: =Unit_Economics!M26 | D26: =B26-C26 | E26: =IF(D26>0, B1/D26, 0) | F26: =E26*B26
A27: Mamaearth Rice Face Scrub | B27: =Unit_Economics!B27 | C27: =Unit_Economics!M27 | D27: =B27-C27 | E27: =IF(D27>0, B1/D27, 0) | F27: =E27*B27
A28: Mamaearth Ubtan Face Scrub | B28: =Unit_Economics!B28 | C28: =Unit_Economics!M28 | D28: =B28-C28 | E28: =IF(D28>0, B1/D28, 0) | F28: =E28*B28
A29: Mamaearth Charcoal Face Mask - 200g | B29: =Unit_Economics!B29 | C29: =Unit_Economics!M29 | D29: =B29-C29 | E29: =IF(D29>0, B1/D29, 0) | F29: =E29*B29
A30: Vitamin C Daily Glow Face Serum - 10ml | B30: =Unit_Economics!B30 | C30: =Unit_Economics!M30 | D30: =B30-C30 | E30: =IF(D30>0, B1/D30, 0) | F30: =E30*B30
A31: Mamaearth Vitamin C Body Lotion | B31: =Unit_Economics!B31 | C31: =Unit_Economics!M31 | D31: =B31-C31 | E31: =IF(D31>0, B1/D31, 0) | F31: =E31*B31
A32: Mamaearth Ubtan Body Lotion | B32: =Unit_Economics!B32 | C32: =Unit_Economics!M32 | D32: =B32-C32 | E32: =IF(D32>0, B1/D32, 0) | F32: =E32*B32
A33: Mamaearth Cocoa Rich Moisturizing Body Lotion with Cocoa Butter & Vitamin E for Intense Moisturization - 400 ml | B33: =Unit_Economics!B33 | C33: =Unit_Economics!M33 | D33: =B33-C33 | E33: =IF(D33>0, B1/D33, 0) | F33: =E33*B33
A34: Mamaearth Tea Tree Body Wash With Tea Tree and Neem For Skin Purification - 300 ml | B34: =Unit_Economics!B34 | C34: =Unit_Economics!M34 | D34: =B34-C34 | E34: =IF(D34>0, B1/D34, 0) | F34: =E34*B34
A35: Milky Soft Shampoo with Oats, Milk and Calendula for Babies - 400 ml | B35: =Unit_Economics!B35 | C35: =Unit_Economics!M35 | D35: =B35-C35 | E35: =IF(D35>0, B1/D35, 0) | F35: =E35*B35
A36: Milky Soft Body Lotion for Babies with Oats, Milk & Calendula – 200ml | B36: =Unit_Economics!B36 | C36: =Unit_Economics!M36 | D36: =B36-C36 | E36: =IF(D36>0, B1/D36, 0) | F36: =E36*B36
A37: Moisturizing Bathing Bar Soap For Babies, pack of 2*75g | B37: =Unit_Economics!B37 | C37: =Unit_Economics!M37 | D37: =B37-C37 | E37: =IF(D37>0, B1/D37, 0) | F37: =E37*B37
A38: Mamaearth Lip Balm | B38: =Unit_Economics!B38 | C38: =Unit_Economics!M38 | D38: =B38-C38 | E38: =IF(D38>0, B1/D38, 0) | F38: =E38*B38
A39: Mamaearth Tinted Lip Balm | B39: =Unit_Economics!B39 | C39: =Unit_Economics!M39 | D39: =B39-C39 | E39: =IF(D39>0, B1/D39, 0) | F39: =E39*B39
A40: Mamaearth Under Eye Cream | B40: =Unit_Economics!B40 | C40: =Unit_Economics!M40 | D40: =B40-C40 | E40: =IF(D40>0, B1/D40, 0) | F40: =E40*B40
A41: Charcoal Black Long Stay Kajal with Vitamin C & Chamomile for 11-Hour Smudge-free Stay | B41: =Unit_Economics!B41 | C41: =Unit_Economics!M41 | D41: =B41-C41 | E41: =IF(D41>0, B1/D41, 0) | F41: =E41*B41

Sheet Dashboard
A1: ONDC vs Amazon Unit Economics Dashboard
A3: Key Metrics
A4: Average Profit per Unit (Amazon) | B4: =AVERAGE(Unit_Economics!N2:N39)
A5: Average Profit per Unit (ONDC) | B5: =AVERAGE(Unit_Economics!O2:O39)
A6: Average Profit Increase % | B6: =AVERAGE(Unit_Economics!P2:P39)
A7: Total Monthly Profit (Amazon) | B7: =SUM(Unit_Economics!Q2:Q39)
A8: Total Monthly Profit (ONDC) | B8: =SUM(Unit_Economics!R2:R39)
A9: Total Monthly Profit Increase (INR) | B9: =B8-B7
A10: Best Performing Product (ONDC) | B10: =INDEX(Unit_Economics!A2:A39,MATCH(MAX(Unit_Economics!O2:O39),Unit_Economics!O2:O39,0))
A12: 📊 Understanding 'Average Profit Increase %': This metric averages the percentage change for each product individually. A negative value (-2.79%) does NOT indicate a loss. ONDC is MORE profitable overall (₹3.38M more per month). The negative percentage occurs because some low-priced products (≤₹300) favor Amazon (0% commission vs ₹1.50 ONDC fee), which pulls down the average. Focus on 'Total Monthly Profit Increase (INR)' which shows the true advantage: ₹3,376,980 positive.
