Workbook

Sheet Parameters
A1: Parameter | B1: Value | C1: Description
A2: Amazon_Commission_pct | B2: 0.18 | C2: Amazon marketplace commission rate (decimal)
A3: ONDC_Commission_pct | B3: 0.06 | C3: ONDC network commission rate (decimal)
A4: Payment_Fee_pct | B4: 0.02 | C4: Payment gateway fee rate (decimal)
A5: Packaging_per_unit | B5: 12 | C5: Packaging cost per unit (INR)
A6: Other_Fees_per_unit | B6: 5 | C6: Other fees per unit (INR)
A7: CAC_Amazon_per_unit | B7: 90 | C7: Customer Acquisition Cost per unit - Amazon (INR)
A8: CAC_ONDC_per_unit | B8: 100 | C8: Customer Acquisition Cost per unit - ONDC (INR)
A9: Default_Fixed_Costs_monthly | B9: 50000 | C9: Monthly fixed costs (INR)

Sheet Product_Data
A1: Product_Name | B1: Category | C1: Size | D1: Selling_Price | E1: Estimated_Weight_g | F1: Monthly_Sales_Units | G1: Cost_of_Goods_est | H1: Logistics_Cost | I1: Data_Source
A2: Mamaearth Onion Hair Oil | B2: Hair Care | C2: 100ml | D2: 399 | E2: 100 | F2: 18000 | G2: 119.7 | H2: 15 | I2: Estimated
A3: Mamaearth Onion Shampoo | B3: Hair Care | C3: 250ml | D3: 177 | E3: 250 | F3: 23400 | G3: 53.1 | H3: 15 | I3: Mamaearth Website
A4: Mamaearth Onion Conditioner | B4: Hair Care | C4: 250ml | D4: 349 | E4: 250 | F4: 18000 | G4: 104.7 | H4: 15 | I4: Mamaearth Website
A5: Rosemary Hair Growth Oil with Rosemary & Methi Dana for Promoting Hair Growth - 100 ml | B5: Hair Care | C5: 100ml | D5: 100 | E5: 100 | F5: 23400 | G5: 30 | H5: 15 | I5: Mamaearth Website
A6: Mamaearth Rosemary Shampoo | B6: Hair Care | C6: 250ml | D6: 310 | E6: 250 | F6: 18000 | G6: 93 | H6: 15 | I6: Mamaearth Website
A7: Mamaearth Argan Hair Mask | B7: Hair Care | C7: 200g | D7: 372 | E7: 200 | F7: 18000 | G7: 111.6 | H7: 15 | I7: Mamaearth Website
A8: Mamaearth Hair Serum | B8: Hair Care | C8: 150ml | D8: 372 | E8: 150 | F8: 18000 | G8: 111.6 | H8: 15 | I8: Mamaearth Website
A9: Mamaearth Onion Hair Growth Serum | B9: Hair Care | C9: 150ml | D9: 799 | E9: 150 | F9: 14400 | G9: 239.7 | H9: 15 | I9: Mamaearth Website
A10: Mamaearth Vitamin C Face Wash | B10: Face Care | C10: 100ml | D10: 399 | E10: 100 | F10: 20000 | G10: 119.7 | H10: 15 | I10: Mamaearth Website
A11: Ubtan Natural Glow Face Wash with Turmeric & Saffron for Tan Removal – 100 ml | B11: Face Care | C11: 100ml | D11: 100 | E11: 100 | F11: 26000 | G11: 30 | H11: 15 | I11: Mamaearth Website
A12: Tea Tree Pimple Control Face Wash with Tea Tree & Salicylic for Oily & Acne-Prone Skin - 100ml | B12: Face Care | C12: 100ml | D12: 100 | E12: 100 | F12: 26000 | G12: 30 | H12: 15 | I12: Mamaearth Website
A13: Mamaearth Aloe Vera Face Wash | B13: Face Care | C13: 100ml | D13: 269 | E13: 100 | F13: 22000 | G13: 80.7 | H13: 15 | I13: Mamaearth Website
... A42: Mamaearth Kajal | B42: Eye Care | C42: 0.35g | D42: 698 | E42: 1 | F42: 8000 | G42: 209.4 | H42: 15 | I42: Mamaearth Website

Sheet Unit_Economics
A1: Product_Name | B1: Selling_Price | C1: Cost_of_Goods | D1: Amazon_Commission_amt | E1: ONDC_Commission_amt | F1: Payment_Gateway_Fee | G1: Logistics_Cost | H1: Packaging_Cost | I1: Other_Fees | J1: CAC_Amazon | K1: CAC_ONDC | L1: Total_Cost_Amazon | M1: Total_Cost_ONDC | N1: Profit_per_unit_Amazon | O1: Profit_per_unit_ONDC | P1: Profit_Change_pct | Q1: Monthly_Profit_Amazon | R1: Monthly_Profit_ONDC
A2: Mamaearth Onion Hair Oil | B2: =Product_Data!D2 | C2: =Product_Data!G2 | D2: =B2*Parameters!B2 | E2: =B2*Parameters!B3 | F2: =B2*Parameters!B4 | G2: =Product_Data!H2 | H2: =Parameters!B5 | I2: =Parameters!B6 | J2: =Parameters!B7 | K2: =Parameters!B8 | L2: =C2+D2+F2+G2+H2+I2+J2 | M2: =C2+E2+F2+G2+H2+I2+K2 | N2: =B2-L2 | O2: =B2-M2 | P2: =(O2-N2)/ABS(N2)*100 | Q2: =N2*Product_Data!F2 | R2: =O2*Product_Data!F2
A3: Mamaearth Onion Shampoo | B3: =Product_Data!D3 | C3: =Product_Data!G3 | D3: =B3*Parameters!B2 | E3: =B3*Parameters!B3 | F3: =B3*Parameters!B4 | G3: =Product_Data!H3 | H3: =Parameters!B5 | I3: =Parameters!B6 | J3: =Parameters!B7 | K3: =Parameters!B8 | L3: =C3+D3+F3+G3+H3+I3+J3 | M3: =C3+E3+F3+G3+H3+I3+K3 | N3: =B3-L3 | O3: =B3-M3 | P3: =(O3-N3)/ABS(N3)*100 | Q3: =N3*Product_Data!F3 | R3: =O3*Product_Data!F3
A4: Mamaearth Onion Conditioner | B4: =Product_Data!D4 | C4: =Product_Data!G4 | D4: =B4*Parameters!B2 | E4: =B4*Parameters!B3 | F4: =B4*Parameters!B4 | G4: =Product_Data!H4 | H4: =Parameters!B5 | I4: =Parameters!B6 | J4: =Parameters!B7 | K4: =Parameters!B8 | L4: =C4+D4+F4+G4+H4+I4+J4 | M4: =C4+E4+F4+G4+H4+I4+K4 | N4: =B4-L4 | O4: =B4-M4 | P4: =(O4-N4)/ABS(N4)*100 | Q4: =N4*Product_Data!F4 | R4: =O4*Product_Data!F4
A5: Rosemary Hair Growth Oil with Rosemary & Methi Dana for Promoting Hair Growth - 100 ml | B5: =Product_Data!D5 | C5: =Product_Data!G5 | D5: =B5*Parameters!B2 | E5: =B5*Parameters!B3 | F5: =B5*Parameters!B4 | G5: =Product_Data!H5 | H5: =Parameters!B5 | I5: =Parameters!B6 | J5: =Parameters!B7 | K5: =Parameters!B8 | L5: =C5+D5+F5+G5+H5+I5+J5 | M5: =C5+E5+F5+G5+H5+I5+K5 | N5: =B5-L5 | O5: =B5-M5 | P5: =(O5-N5)/ABS(N5)*100 | Q5: =N5*Product_Data!F5 | R5: =O5*Product_Data!F5
A6: Mamaearth Rosemary Shampoo | B6: =Product_Data!D6 | C6: =Product_Data!G6 | D6: =B6*Parameters!B2 | E6: =B6*Parameters!B3 | F6: =B6*Parameters!B4 | G6: =Product_Data!H6 | H6: =Parameters!B5 | I6: =Parameters!B6 | J6: =Parameters!B7 | K6: =Parameters!B8 | L6: =C6+D6+F6+G6+H6+I6+J6 | M6: =C6+E6+F6+G6+H6+I6+K6 | N6: =B6-L6 | O6: =B6-M6 | P6: =(O6-N6)/ABS(N6)*100 | Q6: =N6*Product_Data!F6 | R6: =O6*Product_Data!F6
A7: Mamaearth Argan Hair Mask | B7: =Product_Data!D7 | C7: =Product_Data!G7 | D7: =B7*Parameters!B2 | E7: =B7*Parameters!B3 | F7: =B7*Parameters!B4 | G7: =Product_Data!H7 | H7: =Parameters!B5 | I7: =Parameters!B6 | J7: =Parameters!B7 | K7: =Parameters!B8 | L7: =C7+D7+F7+G7+H7+I7+J7 | M7: =C7+E7+F7+G7+H7+I7+K7 | N7: =B7-L7 | O7: =B7-M7 | P7: =(O7-N7)/ABS(N7)*100 | Q7: =N7*Product_Data!F7 | R7: =O7*Product_Data!F7
A8: Mamaearth Hair Serum | B8: =Product_Data!D8 | C8: =Product_Data!G8 | D8: =B8*Parameters!B2 | E8: =B8*Parameters!B3 | F8: =B8*Parameters!B4 | G8: =Product_Data!H8 | H8: =Parameters!B5 | I8: =Parameters!B6 | J8: =Parameters!B7 | K8: =Parameters!B8 | L8: =C8+D8+F8+G8+H8+I8+J8 | M8: =C8+E8+F8+G8+H8+I8+K8 | N8: =B8-L8 | O8: =B8-M8 | P8: =(O8-N8)/ABS(N8)*100 | Q8: =N8*Product_Data!F8 | R8: =O8*Product_Data!F8
A9: Mamaearth Onion Hair Growth Serum | B9: =Product_Data!D9 | C9: =Product_Data!G9 | D9: =B9*Parameters!B2 | E9: =B9*Parameters!B3 | F9: =B9*Parameters!B4 | G9: =Product_Data!H9 | H9: =Parameters!B5 | I9: =Parameters!B6 | J9: =Parameters!B7 | K9: =Parameters!B8 | L9: =C9+D9+F9+G9+H9+I9+J9 | M9: =C9+E9+F9+G9+H9+I9+K9 | N9: =B9-L9 | O9: =B9-M9 | P9: =(O9-N9)/ABS(N9)*100 | Q9: =N9*Product_Data!F9 | R9: =O9*Product_Data!F9
A10: Mamaearth Vitamin C Face Wash | B10: =Product_Data!D10 | C10: =Product_Data!G10 | D10: =B10*Parameters!B2 | E10: =B10*Parameters!B3 | F10: =B10*Parameters!B4 | G10: =Product_Data!H10 | H10: =Parameters!B5 | I10: =Parameters!B6 | J10: =Parameters!B7 | K10: =Parameters!B8 | L10: =C10+D10+F10+G10+H10+I10+J10 | M10: =C10+E10+F10+G10+H10+I10+K10 | N10: =B10-L10 | O10: =B10-M10 | P10: =(O10-N10)/ABS(N10)*100 | Q10: =N10*Product_Data!F10 | R10: =O10*Product_Data!F10
A11: Ubtan Natural Glow Face Wash with Turmeric & Saffron for Tan Removal – 100 ml | B11: =Product_Data!D11 | C11: =Product_Data!G11 | D11: =B11*Parameters!B2 | E11: =B11*Parameters!B3 | F11: =B11*Parameters!B4 | G11: =Product_Data!H11 | H11: =Parameters!B5 | I11: =Parameters!B6 | J11: =Parameters!B7 | K11: =Parameters!B8 | L11: =C11+D11+F11+G11+H11+I11+J11 | M11: =C11+E11+F11+G11+H11+I11+K11 | N11: =B11-L11 | O11: =B11-M11 | P11: =(O11-N11)/ABS(N11)*100 | Q11: =N11*Product_Data!F11 | R11: =O11*Product_Data!F11
A12: Tea Tree Pimple Control Face Wash with Tea Tree & Salicylic for Oily & Acne-Prone Skin - 100ml | B12: =Product_Data!D12 | C12: =Product_Data!G12 | D12: =B12*Parameters!B2 | E12: =B12*Parameters!B3 | F12: =B12*Parameters!B4 | G12: =Product_Data!H12 | H12: =Parameters!B5 | I12: =Parameters!B6 | J12: =Parameters!B7 | K12: =Parameters!B8 | L12: =C12+D12+F12+G12+H12+I12+J12 | M12: =C12+E12+F12+G12+H12+I12+K12 | N12: =B12-L12 | O12: =B12-M12 | P12: =(O12-N12)/ABS(N12)*100 | Q12: =N12*Product_Data!F12 | R12: =O12*Product_Data!F12
A13: Mamaearth Aloe Vera Face Wash | B13: =Product_Data!D13 | C13: =Product_Data!G13 | D13: =B13*Parameters!B2 | E13: =B13*Parameters!B3 | F13: =B13*Parameters!B4 | G13: =Product_Data!H13 | H13: =Parameters!B5 | I13: =Parameters!B6 | J13: =Parameters!B7 | K13: =Parameters!B8 | L13: =C13+D13+F13+G13+H13+I13+J13 | M13: =C13+E13+F13+G13+H13+I13+K13 | N13: =B13-L13 | O13: =B13-M13 | P13: =(O13-N13)/ABS(N13)*100 | Q13: =N13*Product_Data!F13 | R13: =O13*Product_Data!F13
A14: Rice Dewy Bright Face Wash With Rice Water & Niacinamide for Glass Skin - 200 ml | B14: =Product_Data!D14 | C14: =Product_Data!G14 | D14: =B14*Parameters!B2 | E14: =B14*Parameters!B3 | F14: =B14*Parameters!B4 | G14: =Product_Data!H14 | H14: =Parameters!B5 | I14: =Parameters!B6 | J14: =Parameters!B7 | K14: =Parameters!B8 | L14: =C14+D14+F14+G14+H14+I14+J14 | M14: =C14+E14+F14+G14+H14+I14+K14 | N14: =B14-L14 | O14: =B14-M14 | P14: =(O14-N14)/ABS(N14)*100 | Q14: =N14*Product_Data!F14 | R14: =O14*Product_Data!F14
A15: Mamaearth Charcoal Face Wash | B15: =Product_Data!D15 | C15: =Product_Data!G15 | D15: =B15*Parameters!B2 | E15: =B15*Parameters!B3 | F15: =B15*Parameters!B4 | G15: =Product_Data!H15 | H15: =Parameters!B5 | I15: =Parameters!B6 | J15: =Parameters!B7 | K15: =Parameters!B8 | L15: =C15+D15+F15+G15+H15+I15+J15 | M15: =C15+E15+F15+G15+H15+I15+K15 | N15: =B15-L15 | O15: =B15-M15 | P15: =(O15-N15)/ABS(N15)*100 | Q15: =N15*Product_Data!F15 | R15: =O15*Product_Data!F15
A16: Mamaearth Bye Bye Blemishes Face Wash | B16: =Product_Data!D16 | C16: =Product_Data!G16 | D16: =B16*Parameters!B2 | E16: =B16*Parameters!B3 | F16: =B16*Parameters!B4 | G16: =Product_Data!H16 | H16: =Parameters!B5 | I16: =Parameters!B6 | J16: =Parameters!B7 | K16: =Parameters!B8 | L16: =C16+D16+F16+G16+H16+I16+J16 | M16: =C16+E16+F16+G16+H16+I16+K16 | N16: =B16-L16 | O16: =B16-M16 | P16: =(O16-N16)/ABS(N16)*100 | Q16: =N16*Product_Data!F16 | R16: =O16*Product_Data!F16
A17: Vitamin C Daily Glow Face Cream With Vitamin C & Turmeric for Skin Illumination - 80 g | B17: =Product_Data!D17 | C17: =Product_Data!G17 | D17: =B17*Parameters!B2 | E17: =B17*Parameters!B3 | F17: =B17*Parameters!B4 | G17: =Product_Data!H17 | H17: =Parameters!B5 | I17: =Parameters!B6 | J17: =Parameters!B7 | K17: =Parameters!B8 | L17: =C17+D17+F17+G17+H17+I17+J17 | M17: =C17+E17+F17+G17+H17+I17+K17 | N17: =B17-L17 | O17: =B17-M17 | P17: =(O17-N17)/ABS(N17)*100 | Q17: =N17*Product_Data!F17 | R17: =O17*Product_Data!F17
A18: Mamaearth Ubtan Face Cream | B18: =Product_Data!D18 | C18: =Product_Data!G18 | D18: =B18*Parameters!B2 | E18: =B18*Parameters!B3 | F18: =B18*Parameters!B4 | G18: =Product_Data!H18 | H18: =Parameters!B5 | I18: =Parameters!B6 | J18: =Parameters!B7 | K18: =Parameters!B8 | L18: =C18+D18+F18+G18+H18+I18+J18 | M18: =C18+E18+F18+G18+H18+I18+K18 | N18: =B18-L18 | O18: =B18-M18 | P18: =(O18-N18)/ABS(N18)*100 | Q18: =N18*Product_Data!F18 | R18: =O18*Product_Data!F18
A19: Mamaearth Vitamin C Night Cream | B19: =Product_Data!D19 | C19: =Product_Data!G19 | D19: =B19*Parameters!B2 | E19: =B19*Parameters!B3 | F19: =B19*Parameters!B4 | G19: =Product_Data!H19 | H19: =Parameters!B5 | I19: =Parameters!B6 | J19: =Parameters!B7 | K19: =Parameters!B8 | L19: =C19+D19+F19+G19+H19+I19+J19 | M19: =C19+E19+F19+G19+H19+I19+K19 | N19: =B19-L19 | O19: =B19-M19 | P19: =(O19-N19)/ABS(N19)*100 | Q19: =N19*Product_Data!F19 | R19: =O19*Product_Data!F19
A20: Mamaearth Aqua Glow Face Cream | B20: =Product_Data!D20 | C20: =Product_Data!G20 | D20: =B20*Parameters!B2 | E20: =B20*Parameters!B3 | F20: =B20*Parameters!B4 | G20: =Product_Data!H20 | H20: =Parameters!B5 | I20: =Parameters!B6 | J20: =Parameters!B7 | K20: =Parameters!B8 | L20: =C20+D20+F20+G20+H20+I20+J20 | M20: =C20+E20+F20+G20+H20+I20+K20 | N20: =B20-L20 | O20: =B20-M20 | P20: =(O20-N20)/ABS(N20)*100 | Q20: =N20*Product_Data!F20 | R20: =O20*Product_Data!F20
A21: Mamaearth Honey Oats Face Cream | B21: =Product_Data!D21 | C21: =Product_Data!G21 | D21: =B21*Parameters!B2 | E21: =B21*Parameters!B3 | F21: =B21*Parameters!B4 | G21: =Product_Data!H21 | H21: =Parameters!B5 | I21: =Parameters!B6 | J21: =Parameters!B7 | K21: =Parameters!B8 | L21: =C21+D21+F21+G21+H21+I21+J21 | M21: =C21+E21+F21+G21+H21+I21+K21 | N21: =B21-L21 | O21: =B21-M21 | P21: =(O21-N21)/ABS(N21)*100 | Q21: =N21*Product_Data!F21 | R21: =O21*Product_Data!F21
A22: Mamaearth Bye Bye Blemishes Face Cream | B22: =Product_Data!D22 | C22: =Product_Data!G22 | D22: =B22*Parameters!B2 | E22: =B22*Parameters!B3 | F22: =B22*Parameters!B4 | G22: =Product_Data!H22 | H22: =Parameters!B5 | I22: =Parameters!B6 | J22: =Parameters!B7 | K22: =Parameters!B8 | L22: =C22+D22+F22+G22+H22+I22+J22 | M22: =C22+E22+F22+G22+H22+I22+K22 | N22: =B22-L22 | O22: =B22-M22 | P22: =(O22-N22)/ABS(N22)*100 | Q22: =N22*Product_Data!F22 | R22: =O22*Product_Data!F22
A23: Mamaearth Vitamin C Face Serum | B23: =Product_Data!D23 | C23: =Product_Data!G23 | D23: =B23*Parameters!B2 | E23: =B23*Parameters!B3 | F23: =B23*Parameters!B4 | G23: =Product_Data!H23 | H23: =Parameters!B5 | I23: =Parameters!B6 | J23: =Parameters!B7 | K23: =Parameters!B8 | L23: =C23+D23+F23+G23+H23+I23+J23 | M23: =C23+E23+F23+G23+H23+I23+K23 | N23: =B23-L23 | O23: =B23-M23 | P23: =(O23-N23)/ABS(N23)*100 | Q23: =N23*Product_Data!F23 | R23: =O23*Product_Data!F23
A24: Mamaearth Retinol Face Serum | B24: =Product_Data!D24 | C24: =Product_Data!G24 | D24: =B24*Parameters!B2 | E24: =B24*Parameters!B3 | F24: =B24*Parameters!B4 | G24: =Product_Data!H24 | H24: =Parameters!B5 | I24: =Parameters!B6 | J24: =Parameters!B7 | K24: =Parameters!B8 | L24: =C24+D24+F24+G24+H24+I24+J24 | M24: =C24+E24+F24+G24+H24+I24+K24 | N24: =B24-L24 | O24: =B24-M24 | P24: =(O24-N24)/ABS(N24)*100 | Q24: =N24*Product_Data!F24 | R24: =O24*Product_Data!F24
A25: Mamaearth Niacinamide Face Serum | B25: =Product_Data!D25 | C25: =Product_Data!G25 | D25: =B25*Parameters!B2 | E25: =B25*Parameters!B3 | F25: =B25*Parameters!B4 | G25: =Product_Data!H25 | H25: =Parameters!B5 | I25: =Parameters!B6 | J25: =Parameters!B7 | K25: =Parameters!B8 | L25: =C25+D25+F25+G25+H25+I25+J25 | M25: =C25+E25+F25+G25+H25+I25+K25 | N25: =B25-L25 | O25: =B25-M25 | P25: =(O25-N25)/ABS(N25)*100 | Q25: =N25*Product_Data!F25 | R25: =O25*Product_Data!F25
A26: Mamaearth Hyaluronic Acid Serum | B26: =Product_Data!D26 | C26: =Product_Data!G26 | D26: =B26*Parameters!B2 | E26: =B26*Parameters!B3 | F26: =B26*Parameters!B4 | G26: =Product_Data!H26 | H26: =Parameters!B5 | I26: =Parameters!B6 | J26: =Parameters!B7 | K26: =Parameters!B8 | L26: =C26+D26+F26+G26+H26+I26+J26 | M26: =C26+E26+F26+G26+H26+I26+K26 | N26: =B26-L26 | O26: =B26-M26 | P26: =(O26-N26)/ABS(N26)*100 | Q26: =N26*Product_Data!F26 | R26: =O26*Product_Data!F26
A27: Mamaearth AHA BHA Face Serum | B27: =Product_Data!D27 | C27: =Product_Data!G27 | D27: =B27*Parameters!B2 | E27: =B27*Parameters!B3 | F27: =B27*Parameters!B4 | G27: =Product_Data!H27 | H27: =Parameters!B5 | I27: =Parameters!B6 | J27: =Parameters!B7 | K27: =Parameters!B8 | L27: =C27+D27+F27+G27+H27+I27+J27 | M27: =C27+E27+F27+G27+H27+I27+K27 | N27: =B27-L27 | O27: =B27-M27 | P27: =(O27-N27)/ABS(N27)*100 | Q27: =N27*Product_Data!F27 | R27: =O27*Product_Data!F27
A28: Mamaearth Rice Face Scrub | B28: =Product_Data!D28 | C28: =Product_Data!G28 | D28: =B28*Parameters!B2 | E28: =B28*Parameters!B3 | F28: =B28*Parameters!B4 | G28: =Product_Data!H28 | H28: =Parameters!B5 | I28: =Parameters!B6 | J28: =Parameters!B7 | K28: =Parameters!B8 | L28: =C28+D28+F28+G28+H28+I28+J28 | M28: =C28+E28+F28+G28+H28+I28+K28 | N28: =B28-L28 | O28: =B28-M28 | P28: =(O28-N28)/ABS(N28)*100 | Q28: =N28*Product_Data!F28 | R28: =O28*Product_Data!F28
A29: Mamaearth Ubtan Face Scrub | B29: =Product_Data!D29 | C29: =Product_Data!G29 | D29: =B29*Parameters!B2 | E29: =B29*Parameters!B3 | F29: =B29*Parameters!B4 | G29: =Product_Data!H29 | H29: =Parameters!B5 | I29: =Parameters!B6 | J29: =Parameters!B7 | K29: =Parameters!B8 | L29: =C29+D29+F29+G29+H29+I29+J29 | M29: =C29+E29+F29+G29+H29+I29+K29 | N29: =B29-L29 | O29: =B29-M29 | P29: =(O29-N29)/ABS(N29)*100 | Q29: =N29*Product_Data!F29 | R29: =O29*Product_Data!F29
A30: Mamaearth Charcoal Face Mask | B30: =Product_Data!D30 | C30: =Product_Data!G30 | D30: =B30*Parameters!B2 | E30: =B30*Parameters!B3 | F30: =B30*Parameters!B4 | G30: =Product_Data!H30 | H30: =Parameters!B5 | I30: =Parameters!B6 | J30: =Parameters!B7 | K30: =Parameters!B8 | L30: =C30+D30+F30+G30+H30+I30+J30 | M30: =C30+E30+F30+G30+H30+I30+K30 | N30: =B30-L30 | O30: =B30-M30 | P30: =(O30-N30)/ABS(N30)*100 | Q30: =N30*Product_Data!F30 | R30: =O30*Product_Data!F30
A31: Mamaearth Vitamin C Face Mask | B31: =Product_Data!D31 | C31: =Product_Data!G31 | D31: =B31*Parameters!B2 | E31: =B31*Parameters!B3 | F31: =B31*Parameters!B4 | G31: =Product_Data!H31 | H31: =Parameters!B5 | I31: =Parameters!B6 | J31: =Parameters!B7 | K31: =Parameters!B8 | L31: =C31+D31+F31+G31+H31+I31+J31 | M31: =C31+E31+F31+G31+H31+I31+K31 | N31: =B31-L31 | O31: =B31-M31 | P31: =(O31-N31)/ABS(N31)*100 | Q31: =N31*Product_Data!F31 | R31: =O31*Product_Data!F31
A32: Mamaearth Vitamin C Body Lotion | B32: =Product_Data!D32 | C32: =Product_Data!G32 | D32: =B32*Parameters!B2 | E32: =B32*Parameters!B3 | F32: =B32*Parameters!B4 | G32: =Product_Data!H32 | H32: =Parameters!B5 | I32: =Parameters!B6 | J32: =Parameters!B7 | K32: =Parameters!B8 | L32: =C32+D32+F32+G32+H32+I32+J32 | M32: =C32+E32+F32+G32+H32+I32+K32 | N32: =B32-L32 | O32: =B32-M32 | P32: =(O32-N32)/ABS(N32)*100 | Q32: =N32*Product_Data!F32 | R32: =O32*Product_Data!F32
A33: Mamaearth Ubtan Body Lotion | B33: =Product_Data!D33 | C33: =Product_Data!G33 | D33: =B33*Parameters!B2 | E33: =B33*Parameters!B3 | F33: =B33*Parameters!B4 | G33: =Product_Data!H33 | H33: =Parameters!B5 | I33: =Parameters!B6 | J33: =Parameters!B7 | K33: =Parameters!B8 | L33: =C33+D33+F33+G33+H33+I33+J33 | M33: =C33+E33+F33+G33+H33+I33+K33 | N33: =B33-L33 | O33: =B33-M33 | P33: =(O33-N33)/ABS(N33)*100 | Q33: =N33*Product_Data!F33 | R33: =O33*Product_Data!F33
A34: Mamaearth Cocoa Body Butter | B34: =Product_Data!D34 | C34: =Product_Data!G34 | D34: =B34*Parameters!B2 | E34: =B34*Parameters!B3 | F34: =B34*Parameters!B4 | G34: =Product_Data!H34 | H34: =Parameters!B5 | I34: =Parameters!B6 | J34: =Parameters!B7 | K34: =Parameters!B8 | L34: =C34+D34+F34+G34+H34+I34+J34 | M34: =C34+E34+F34+G34+H34+I34+K34 | N34: =B34-L34 | O34: =B34-M34 | P34: =(O34-N34)/ABS(N34)*100 | Q34: =N34*Product_Data!F34 | R34: =O34*Product_Data!F34
A35: Mamaearth Tea Tree Body Wash | B35: =Product_Data!D35 | C35: =Product_Data!G35 | D35: =B35*Parameters!B2 | E35: =B35*Parameters!B3 | F35: =B35*Parameters!B4 | G35: =Product_Data!H35 | H35: =Parameters!B5 | I35: =Parameters!B6 | J35: =Parameters!B7 | K35: =Parameters!B8 | L35: =C35+D35+F35+G35+H35+I35+J35 | M35: =C35+E35+F35+G35+H35+I35+K35 | N35: =B35-L35 | O35: =B35-M35 | P35: =(O35-N35)/ABS(N35)*100 | Q35: =N35*Product_Data!F35 | R35: =O35*Product_Data!F35
A36: Mamaearth Baby Shampoo | B36: =Product_Data!D36 | C36: =Product_Data!G36 | D36: =B36*Parameters!B2 | E36: =B36*Parameters!B3 | F36: =B36*Parameters!B4 | G36: =Product_Data!H36 | H36: =Parameters!B5 | I36: =Parameters!B6 | J36: =Parameters!B7 | K36: =Parameters!B8 | L36: =C36+D36+F36+G36+H36+I36+J36 | M36: =C36+E36+F36+G36+H36+I36+K36 | N36: =B36-L36 | O36: =B36-M36 | P36: =(O36-N36)/ABS(N36)*100 | Q36: =N36*Product_Data!F36 | R36: =O36*Product_Data!F36
A37: Mamaearth Baby Lotion | B37: =Product_Data!D37 | C37: =Product_Data!G37 | D37: =B37*Parameters!B2 | E37: =B37*Parameters!B3 | F37: =B37*Parameters!B4 | G37: =Product_Data!H37 | H37: =Parameters!B5 | I37: =Parameters!B6 | J37: =Parameters!B7 | K37: =Parameters!B8 | L37: =C37+D37+F37+G37+H37+I37+J37 | M37: =C37+E37+F37+G37+H37+I37+K37 | N37: =B37-L37 | O37: =B37-M37 | P37: =(O37-N37)/ABS(N37)*100 | Q37: =N37*Product_Data!F37 | R37: =O37*Product_Data!F37
A38: Mamaearth Baby Soap | B38: =Product_Data!D38 | C38: =Product_Data!G38 | D38: =B38*Parameters!B2 | E38: =B38*Parameters!B3 | F38: =B38*Parameters!B4 | G38: =Product_Data!H38 | H38: =Parameters!B5 | I38: =Parameters!B6 | J38: =Parameters!B7 | K38: =Parameters!B8 | L38: =C38+D38+F38+G38+H38+I38+J38 | M38: =C38+E38+F38+G38+H38+I38+K38 | N38: =B38-L38 | O38: =B38-M38 | P38: =(O38-N38)/ABS(N38)*100 | Q38: =N38*Product_Data!F38 | R38: =O38*Product_Data!F38
A39: Mamaearth Lip Balm | B39: =Product_Data!D39 | C39: =Product_Data!G39 | D39: =B39*Parameters!B2 | E39: =B39*Parameters!B3 | F39: =B39*Parameters!B4 | G39: =Product_Data!H39 | H39: =Parameters!B5 | I39: =Parameters!B6 | J39: =Parameters!B7 | K39: =Parameters!B8 | L39: =C39+D39+F39+G39+H39+I39+J39 | M39: =C39+E39+F39+G39+H39+I39+K39 | N39: =B39-L39 | O39: =B39-M39 | P39: =(O39-N39)/ABS(N39)*100 | Q39: =N39*Product_Data!F39 | R39: =O39*Product_Data!F39
A40: Mamaearth Tinted Lip Balm | B40: =Product_Data!D40 | C40: =Product_Data!G40 | D40: =B40*Parameters!B2 | E40: =B40*Parameters!B3 | F40: =B40*Parameters!B4 | G40: =Product_Data!H40 | H40: =Parameters!B5 | I40: =Parameters!B6 | J40: =Parameters!B7 | K40: =Parameters!B8 | L40: =C40+D40+F40+G40+H40+I40+J40 | M40: =C40+E40+F40+G40+H40+I40+K40 | N40: =B40-L40 | O40: =B40-M40 | P40: =(O40-N40)/ABS(N40)*100 | Q40: =N40*Product_Data!F40 | R40: =O40*Product_Data!F40
...

Sheet Scenario_Analysis
A1: Scenario Parameter Changes (%):
A2: CAC Amazon % Change | B2: 0
A3: CAC ONDC % Change | B3: 0
A4: Logistics % Change | B4: 0
A5: Product_Name | B5: Base_Profit_ONDC | C5: Adjusted_CAC_ONDC | D5: Adjusted_Logistics | E5: Adjusted_ONDC_Comm | F5: Adjusted_Total_Cost_ONDC | G5: Adjusted_Profit_ONDC | H5: Profit_Change_vs_Base
A6: Mamaearth Onion Hair Oil | B6: =Unit_Economics!O6 | C6: =Parameters!B8*(1+B4) | D6: =Unit_Economics!G6*(1+B5) | E6: =Unit_Economics!B6*Parameters!B3*(1+B6) | F6: =Unit_Economics!C6+E6+Unit_Economics!F6+D6+C6+Parameters!B5+Parameters!B6 | G6: =Unit_Economics!B6-F6 | H6: =(G6-B6)/ABS(B6)*100
A7: Mamaearth Onion Shampoo | B7: =Unit_Economics!O7 | C7: =Parameters!B8*(1+B4) | D7: =Unit_Economics!G7*(1+B5) | E7: =Unit_Economics!B7*Parameters!B3*(1+B6) | F7: =Unit_Economics!C7+E7+Unit_Economics!F7+D7+C7+Parameters!B5+Parameters!B6 | G7: =Unit_Economics!B7-F7 | H7: =(G7-B7)/ABS(B7)*100
A8: Mamaearth Onion Conditioner | B8: =Unit_Economics!O8 | C8: =Parameters!B8*(1+B4) | D8: =Unit_Economics!G8*(1+B5) | E8: =Unit_Economics!B8*Parameters!B3*(1+B6) | F8: =Unit_Economics!C8+E8+Unit_Economics!F8+D8+C8+Parameters!B5+Parameters!B6 | G8: =Unit_Economics!B8-F8 | H8: =(G8-B8)/ABS(B8)*100
A9: Rosemary Hair Growth Oil with Rosemary & Methi Dana for Promoting Hair Growth - 100 ml | B9: =Unit_Economics!O9 | C9: =Parameters!B8*(1+B4) | D9: =Unit_Economics!G9*(1+B5) | E9: =Unit_Economics!B9*Parameters!B3*(1+B6) | F9: =Unit_Economics!C9+E9+Unit_Economics!F9+D9+C9+Parameters!B5+Parameters!B6 | G9: =Unit_Economics!B9-F9 | H9: =(G9-B9)/ABS(B9)*100
A10: Mamaearth Rosemary Shampoo | B10: =Unit_Economics!O10 | C10: =Parameters!B8*(1+B4) | D10: =Unit_Economics!G10*(1+B5) | E10: =Unit_Economics!B10*Parameters!B3*(1+B6) | F10: =Unit_Economics!C10+E10+Unit_Economics!F10+D10+C10+Parameters!B5+Parameters!B6 | G10: =Unit_Economics!B10-F10 | H10: =(G10-B10)/ABS(B10)*100
A11: Mamaearth Argan Hair Mask | B11: =Unit_Economics!O11 | C11: =Parameters!B8*(1+B4) | D11: =Unit_Economics!G11*(1+B5) | E11: =Unit_Economics!B11*Parameters!B3*(1+B6) | F11: =Unit_Economics!C11+E11+Unit_Economics!F11+D11+C11+Parameters!B5+Parameters!B6 | G11: =Unit_Economics!B11-F11 | H11: =(G11-B11)/ABS(B11)*100
A12: Mamaearth Hair Serum | B12: =Unit_Economics!O12 | C12: =Parameters!B8*(1+B4) | D12: =Unit_Economics!G12*(1+B5) | E12: =Unit_Economics!B12*Parameters!B3*(1+B6) | F12: =Unit_Economics!C12+E12+Unit_Economics!F12+D12+C12+Parameters!B5+Parameters!B6 | G12: =Unit_Economics!B12-F12 | H12: =(G12-B12)/ABS(B12)*100
A13: Mamaearth Onion Hair Growth Serum | B13: =Unit_Economics!O13 | C13: =Parameters!B8*(1+B4) | D13: =Unit_Economics!G13*(1+B5) | E13: =Unit_Economics!B13*Parameters!B3*(1+B6) | F13: =Unit_Economics!C13+E13+Unit_Economics!F13+D13+C13+Parameters!B5+Parameters!B6 | G13: =Unit_Economics!B13-F13 | H13: =(G13-B13)/ABS(B13)*100
A14: Mamaearth Vitamin C Face Wash | B14: =Unit_Economics!O14 | C14: =Parameters!B8*(1+B4) | D14: =Unit_Economics!G14*(1+B5) | E14: =Unit_Economics!B14*Parameters!B3*(1+B6) | F14: =Unit_Economics!C14+E14+Unit_Economics!F14+D14+C14+Parameters!B5+Parameters!B6 | G14: =Unit_Economics!B14-F14 | H14: =(G14-B14)/ABS(B14)*100
A15: Ubtan Natural Glow Face Wash with Turmeric & Saffron for Tan Removal – 100 ml | B15: =Unit_Economics!O15 | C15: =Parameters!B8*(1+B4) | D15: =Unit_Economics!G15*(1+B5) | E15: =Unit_Economics!B15*Parameters!B3*(1+B6) | F15: =Unit_Economics!C15+E15+Unit_Economics!F15+D15+C15+Parameters!B5+Parameters!B6 | G15: =Unit_Economics!B15-F15 | H15: =(G15-B15)/ABS(B15)*100
A16: Tea Tree Pimple Control Face Wash with Tea Tree & Salicylic for Oily & Acne-Prone Skin - 100ml | B16: =Unit_Economics!O16 | C16: =Parameters!B8*(1+B4) | D16: =Unit_Economics!G16*(1+B5) | E16: =Unit_Economics!B16*Parameters!B3*(1+B6) | F16: =Unit_Economics!C16+E16+Unit_Economics!F16+D16+C16+Parameters!B5+Parameters!B6 | G16: =Unit_Economics!B16-F16 | H16: =(G16-B16)/ABS(B16)*100
A17: Mamaearth Aloe Vera Face Wash | B17: =Unit_Economics!O17 | C17: =Parameters!B8*(1+B4) | D17: =Unit_Economics!G17*(1+B5) | E17: =Unit_Economics!B17*Parameters!B3*(1+B6) | F17: =Unit_Economics!C17+E17+Unit_Economics!F17+D17+C17+Parameters!B5+Parameters!B6 | G17: =Unit_Economics!B17-F17 | H17: =(G17-B17)/ABS(B17)*100
A18: Rice Dewy Bright Face Wash With Rice Water & Niacinamide for Glass Skin - 200 ml | B18: =Unit_Economics!O18 | C18: =Parameters!B8*(1+B4) | D18: =Unit_Economics!G18*(1+B5) | E18: =Unit_Economics!B18*Parameters!B3*(1+B6) | F18: =Unit_Economics!C18+E18+Unit_Economics!F18+D18+C18+Parameters!B5+Parameters!B6 | G18: =Unit_Economics!B18-F18 | H18: =(G18-B18)/ABS(B18)*100
A19: Mamaearth Charcoal Face Wash | B19: =Unit_Economics!O19 | C19: =Parameters!B8*(1+B4) | D19: =Unit_Economics!G19*(1+B5) | E19: =Unit_Economics!B19*Parameters!B3*(1+B6) | F19: =Unit_Economics!C19+E19+Unit_Economics!F19+D19+C19+Parameters!B5+Parameters!B6 | G19: =Unit_Economics!B19-F19 | H19: =(G19-B19)/ABS(B19)*100
A20: Mamaearth Bye Bye Blemishes Face Wash | B20: =Unit_Economics!O20 | C20: =Parameters!B8*(1+B4) | D20: =Unit_Economics!G20*(1+B5) | E20: =Unit_Economics!B20*Parameters!B3*(1+B6) | F20: =Unit_Economics!C20+E20+Unit_Economics!F20+D20+C20+Parameters!B5+Parameters!B6 | G20: =Unit_Economics!B20-F20 | H20: =(G20-B20)/ABS(B20)*100
A21: Vitamin C Daily Glow Face Cream With Vitamin C & Turmeric for Skin Illumination - 80 g | B21: =Unit_Economics!O21 | C21: =Parameters!B8*(1+B4) | D21: =Unit_Economics!G21*(1+B5) | E21: =Unit_Economics!B21*Parameters!B3*(1+B6) | F21: =Unit_Economics!C21+E21+Unit_Economics!F21+D21+C21+Parameters!B5+Parameters!B6 | G21: =Unit_Economics!B21-F21 | H21: =(G21-B21)/ABS(B21)*100
A22: Mamaearth Ubtan Face Cream | B22: =Unit_Economics!O22 | C22: =Parameters!B8*(1+B4) | D22: =Unit_Economics!G22*(1+B5) | E22: =Unit_Economics!B22*Parameters!B3*(1+B6) | F22: =Unit_Economics!C22+E22+Unit_Economics!F22+D22+C22+Parameters!B5+Parameters!B6 | G22: =Unit_Economics!B22-F22 | H22: =(G22-B22)/ABS(B22)*100
A23: Mamaearth Vitamin C Night Cream | B23: =Unit_Economics!O23 | C23: =Parameters!B8*(1+B4) | D23: =Unit_Economics!G23*(1+B5) | E23: =Unit_Economics!B23*Parameters!B3*(1+B6) | F23: =Unit_Economics!C23+E23+Unit_Economics!F23+D23+C23+Parameters!B5+Parameters!B6 | G23: =Unit_Economics!B23-F23 | H23: =(G23-B23)/ABS(B23)*100
A24: Mamaearth Aqua Glow Face Cream | B24: =Unit_Economics!O24 | C24: =Parameters!B8*(1+B4) | D24: =Unit_Economics!G24*(1+B5) | E24: =Unit_Economics!B24*Parameters!B3*(1+B6) | F24: =Unit_Economics!C24+E24+Unit_Economics!F24+D24+C24+Parameters!B5+Parameters!B6 | G24: =Unit_Economics!B24-F24 | H24: =(G24-B24)/ABS(B24)*100
A25: Mamaearth Honey Oats Face Cream | B25: =Unit_Economics!O25 | C25: =Parameters!B8*(1+B4) | D25: =Unit_Economics!G25*(1+B5) | E25: =Unit_Economics!B25*Parameters!B3*(1+B6) | F25: =Unit_Economics!C25+E25+Unit_Economics!F25+D25+C25+Parameters!B5+Parameters!B6 | G25: =Unit_Economics!B25-F25 | H25: =(G25-B25)/ABS(B25)*100
A26: Mamaearth Bye Bye Blemishes Face Cream | B26: =Unit_Economics!O26 | C26: =Parameters!B8*(1+B4) | D26: =Unit_Economics!G26*(1+B5) | E26: =Unit_Economics!B26*Parameters!B3*(1+B6) | F26: =Unit_Economics!C26+E26+Unit_Economics!F26+D26+C26+Parameters!B5+Parameters!B6 | G26: =Unit_Economics!B26-F26 | H26: =(G26-B26)/ABS(B26)*100
A27: Mamaearth Vitamin C Face Serum | B27: =Unit_Economics!O27 | C27: =Parameters!B8*(1+B4) | D27: =Unit_Economics!G27*(1+B5) | E27: =Unit_Economics!B27*Parameters!B3*(1+B6) | F27: =Unit_Economics!C27+E27+Unit_Economics!F27+D27+C27+Parameters!B5+Parameters!B6 | G27: =Unit_Economics!B27-F27 | H27: =(G27-B27)/ABS(B27)*100
A28: Mamaearth Retinol Face Serum | B28: =Unit_Economics!O28 | C28: =Parameters!B8*(1+B4) | D28: =Unit_Economics!G28*(1+B5) | E28: =Unit_Economics!B28*Parameters!B3*(1+B6) | F28: =Unit_Economics!C28+E28+Unit_Economics!F28+D28+C28+Parameters!B5+Parameters!B6 | G28: =Unit_Economics!B28-F28 | H28: =(G28-B28)/ABS(B28)*100
A29: Mamaearth Niacinamide Face Serum | B29: =Unit_Economics!O29 | C29: =Parameters!B8*(1+B4) | D29: =Unit_Economics!G29*(1+B5) | E29: =Unit_Economics!B29*Parameters!B3*(1+B6) | F29: =Unit_Economics!C29+E29+Unit_Economics!F29+D29+C29+Parameters!B5+Parameters!B6 | G29: =Unit_Economics!B29-F29 | H29: =(G29-B29)/ABS(B29)*100
A30: Mamaearth Hyaluronic Acid Serum | B30: =Unit_Economics!O30 | C30: =Parameters!B8*(1+B4) | D30: =Unit_Economics!G30*(1+B5) | E30: =Unit_Economics!B30*Parameters!B3*(1+B6) | F30: =Unit_Economics!C30+E30+Unit_Economics!F30+D30+C30+Parameters!B5+Parameters!B6 | G30: =Unit_Economics!B30-F30 | H30: =(G30-B30)/ABS(B30)*100
A31: Mamaearth AHA BHA Face Serum | B31: =Unit_Economics!O31 | C31: =Parameters!B8*(1+B4) | D31: =Unit_Economics!G31*(1+B5) | E31: =Unit_Economics!B31*Parameters!B3*(1+B6) | F31: =Unit_Economics!C31+E31+Unit_Economics!F31+D31+C31+Parameters!B5+Parameters!B6 | G31: =Unit_Economics!B31-F31 | H31: =(G31-B31)/ABS(B31)*100
A32: Mamaearth Rice Face Scrub | B32: =Unit_Economics!O32 | C32: =Parameters!B8*(1+B4) | D32: =Unit_Economics!G32*(1+B5) | E32: =Unit_Economics!B32*Parameters!B3*(1+B6) | F32: =Unit_Economics!C32+E32+Unit_Economics!F32+D32+C32+Parameters!B5+Parameters!B6 | G32: =Unit_Economics!B32-F32 | H32: =(G32-B32)/ABS(B32)*100
A33: Mamaearth Ubtan Face Scrub | B33: =Unit_Economics!O33 | C33: =Parameters!B8*(1+B4) | D33: =Unit_Economics!G33*(1+B5) | E33: =Unit_Economics!B33*Parameters!B3*(1+B6) | F33: =Unit_Economics!C33+E33+Unit_Economics!F33+D33+C33+Parameters!B5+Parameters!B6 | G33: =Unit_Economics!B33-F33 | H33: =(G33-B33)/ABS(B33)*100
A34: Mamaearth Charcoal Face Mask | B34: =Unit_Economics!O34 | C34: =Parameters!B8*(1+B4) | D34: =Unit_Economics!G34*(1+B5) | E34: =Unit_Economics!B34*Parameters!B3*(1+B6) | F34: =Unit_Economics!C34+E34+Unit_Economics!F34+D34+C34+Parameters!B5+Parameters!B6 | G34: =Unit_Economics!B34-F34 | H34: =(G34-B34)/ABS(B34)*100
A35: Mamaearth Vitamin C Face Mask | B35: =Unit_Economics!O35 | C35: =Parameters!B8*(1+B4) | D35: =Unit_Economics!G35*(1+B5) | E35: =Unit_Economics!B35*Parameters!B3*(1+B6) | F35: =Unit_Economics!C35+E35+Unit_Economics!F35+D35+C35+Parameters!B5+Parameters!B6 | G35: =Unit_Economics!B35-F35 | H35: =(G35-B35)/ABS(B35)*100
A36: Mamaearth Vitamin C Body Lotion | B36: =Unit_Economics!O36 | C36: =Parameters!B8*(1+B4) | D36: =Unit_Economics!G36*(1+B5) | E36: =Unit_Economics!B36*Parameters!B3*(1+B6) | F36: =Unit_Economics!C36+E36+Unit_Economics!F36+D36+C36+Parameters!B5+Parameters!B6 | G36: =Unit_Economics!B36-F36 | H36: =(G36-B36)/ABS(B36)*100
A37: Mamaearth Ubtan Body Lotion | B37: =Unit_Economics!O37 | C37: =Parameters!B8*(1+B4) | D37: =Unit_Economics!G37*(1+B5) | E37: =Unit_Economics!B37*Parameters!B3*(1+B6) | F37: =Unit_Economics!C37+E37+Unit_Economics!F37+D37+C37+Parameters!B5+Parameters!B6 | G37: =Unit_Economics!B37-F37 | H37: =(G37-B37)/ABS(B37)*100
A38: Mamaearth Cocoa Body Butter | B38: =Unit_Economics!O38 | C38: =Parameters!B8*(1+B4) | D38: =Unit_Economics!G38*(1+B5) | E38: =Unit_Economics!B38*Parameters!B3*(1+B6) | F38: =Unit_Economics!C38+E38+Unit_Economics!F38+D38+C38+Parameters!B5+Parameters!B6 | G38: =Unit_Economics!B38-F38 | H38: =(G38-B38)/ABS(B38)*100
A39: Mamaearth Tea Tree Body Wash | B39: =Unit_Economics!O39 | C39: =Parameters!B8*(1+B4) | D39: =Unit_Economics!G39*(1+B5) | E39: =Unit_Economics!B39*Parameters!B3*(1+B6) | F39: =Unit_Economics!C39+E39+Unit_Economics!F39+D39+C39+Parameters!B5+Parameters!B6 | G39: =Unit_Economics!B39-F39 | H39: =(G39-B39)/ABS(B39)*100
A40: Mamaearth Baby Shampoo | B40: =Unit_Economics!O40 | C40: =Parameters!B8*(1+B4) | D40: =Unit_Economics!G40*(1+B5) | E40: =Unit_Economics!B40*Parameters!B3*(1+B6) | F40: =Unit_Economics!C40+E40+Unit_Economics!F40+D40+C40+Parameters!B5+Parameters!B6 | G40: =Unit_Economics!B40-F40 | H40: =(G40-B40)/ABS(B40)*100
...

Sheet Break_Even
A1: Fixed Costs (Monthly): | B1: =Parameters!B9
A3: Product_Name | B3: Selling_Price | C3: Total_Variable_Cost_ONDC | D3: Contribution_per_unit_ONDC | E3: Break_even_units | F3: Break_even_revenue
A4: Mamaearth Onion Hair Oil | B4: =Unit_Economics!B4 | C4: =Unit_Economics!M4 | D4: =B4-C4 | E4: =IF(D4>0, B1/D4, 0) | F4: =E4*B4
A5: Mamaearth Onion Shampoo | B5: =Unit_Economics!B5 | C5: =Unit_Economics!M5 | D5: =B5-C5 | E5: =IF(D5>0, B1/D5, 0) | F5: =E5*B5
A6: Mamaearth Onion Conditioner | B6: =Unit_Economics!B6 | C6: =Unit_Economics!M6 | D6: =B6-C6 | E6: =IF(D6>0, B1/D6, 0) | F6: =E6*B6
A7: Rosemary Hair Growth Oil with Rosemary & Methi Dana for Promoting Hair Growth - 100 ml | B7: =Unit_Economics!B7 | C7: =Unit_Economics!M7 | D7: =B7-C7 | E7: =IF(D7>0, B1/D7, 0) | F7: =E7*B7
A8: Mamaearth Rosemary Shampoo | B8: =Unit_Economics!B8 | C8: =Unit_Economics!M8 | D8: =B8-C8 | E8: =IF(D8>0, B1/D8, 0) | F8: =E8*B8
A9: Mamaearth Argan Hair Mask | B9: =Unit_Economics!B9 | C9: =Unit_Economics!M9 | D9: =B9-C9 | E9: =IF(D9>0, B1/D9, 0) | F9: =E9*B9
A10: Mamaearth Hair Serum | B10: =Unit_Economics!B10 | C10: =Unit_Economics!M10 | D10: =B10-C10 | E10: =IF(D10>0, B1/D10, 0) | F10: =E10*B10
A11: Mamaearth Onion Hair Growth Serum | B11: =Unit_Economics!B11 | C11: =Unit_Economics!M11 | D11: =B11-C11 | E11: =IF(D11>0, B1/D11, 0) | F11: =E11*B11
A12: Mamaearth Vitamin C Face Wash | B12: =Unit_Economics!B12 | C12: =Unit_Economics!M12 | D12: =B12-C12 | E12: =IF(D12>0, B1/D12, 0) | F12: =E12*B12
A13: Ubtan Natural Glow Face Wash with Turmeric & Saffron for Tan Removal – 100 ml | B13: =Unit_Economics!B13 | C13: =Unit_Economics!M13 | D13: =B13-C13 | E13: =IF(D13>0, B1/D13, 0) | F13: =E13*B13
A14: Tea Tree Pimple Control Face Wash with Tea Tree & Salicylic for Oily & Acne-Prone Skin - 100ml | B14: =Unit_Economics!B14 | C14: =Unit_Economics!M14 | D14: =B14-C14 | E14: =IF(D14>0, B1/D14, 0) | F14: =E14*B14
A15: Mamaearth Aloe Vera Face Wash | B15: =Unit_Economics!B15 | C15: =Unit_Economics!M15 | D15: =B15-C15 | E15: =IF(D15>0, B1/D15, 0) | F15: =E15*B15
A16: Rice Dewy Bright Face Wash With Rice Water & Niacinamide for Glass Skin - 200 ml | B16: =Unit_Economics!B16 | C16: =Unit_Economics!M16 | D16: =B16-C16 | E16: =IF(D16>0, B1/D16, 0) | F16: =E16*B16
A17: Mamaearth Charcoal Face Wash | B17: =Unit_Economics!B17 | C17: =Unit_Economics!M17 | D17: =B17-C17 | E17: =IF(D17>0, B1/D17, 0) | F17: =E17*B17
A18: Mamaearth Bye Bye Blemishes Face Wash | B18: =Unit_Economics!B18 | C18: =Unit_Economics!M18 | D18: =B18-C18 | E18: =IF(D18>0, B1/D18, 0) | F18: =E18*B18
A19: Vitamin C Daily Glow Face Cream With Vitamin C & Turmeric for Skin Illumination - 80 g | B19: =Unit_Economics!B19 | C19: =Unit_Economics!M19 | D19: =B19-C19 | E19: =IF(D19>0, B1/D19, 0) | F19: =E19*B19
A20: Mamaearth Ubtan Face Cream | B20: =Unit_Economics!B20 | C20: =Unit_Economics!M20 | D20: =B20-C20 | E20: =IF(D20>0, B1/D20, 0) | F20: =E20*B20
A21: Mamaearth Vitamin C Night Cream | B21: =Unit_Economics!B21 | C21: =Unit_Economics!M21 | D21: =B21-C21 | E21: =IF(D21>0, B1/D21, 0) | F21: =E21*B21
A22: Mamaearth Aqua Glow Face Cream | B22: =Unit_Economics!B22 | C22: =Unit_Economics!M22 | D22: =B22-C22 | E22: =IF(D22>0, B1/D22, 0) | F22: =E22*B22
A23: Mamaearth Honey Oats Face Cream | B23: =Unit_Economics!B23 | C23: =Unit_Economics!M23 | D23: =B23-C23 | E23: =IF(D23>0, B1/D23, 0) | F23: =E23*B23
A24: Mamaearth Bye Bye Blemishes Face Cream | B24: =Unit_Economics!B24 | C24: =Unit_Economics!M24 | D24: =B24-C24 | E24: =IF(D24>0, B1/D24, 0) | F24: =E24*B24
A25: Mamaearth Vitamin C Face Serum | B25: =Unit_Economics!B25 | C25: =Unit_Economics!M25 | D25: =B25-C25 | E25: =IF(D25>0, B1/D25, 0) | F25: =E25*B25
A26: Mamaearth Retinol Face Serum | B26: =Unit_Economics!B26 | C26: =Unit_Economics!M26 | D26: =B26-C26 | E26: =IF(D26>0, B1/D26, 0) | F26: =E26*B26
A27: Mamaearth Niacinamide Face Serum | B27: =Unit_Economics!B27 | C27: =Unit_Economics!M27 | D27: =B27-C27 | E27: =IF(D27>0, B1/D27, 0) | F27: =E27*B27
A28: Mamaearth Hyaluronic Acid Serum | B28: =Unit_Economics!B28 | C28: =Unit_Economics!M28 | D28: =B28-C28 | E28: =IF(D28>0, B1/D28, 0) | F28: =E28*B28
A29: Mamaearth AHA BHA Face Serum | B29: =Unit_Economics!B29 | C29: =Unit_Economics!M29 | D29: =B29-C29 | E29: =IF(D29>0, B1/D29, 0) | F29: =E29*B29
A30: Mamaearth Rice Face Scrub | B30: =Unit_Economics!B30 | C30: =Unit_Economics!M30 | D30: =B30-C30 | E30: =IF(D30>0, B1/D30, 0) | F30: =E30*B30
A31: Mamaearth Ubtan Face Scrub | B31: =Unit_Economics!B31 | C31: =Unit_Economics!M31 | D31: =B31-C31 | E31: =IF(D31>0, B1/D31, 0) | F31: =E31*B31
A32: Mamaearth Charcoal Face Mask | B32: =Unit_Economics!B32 | C32: =Unit_Economics!M32 | D32: =B32-C32 | E32: =IF(D32>0, B1/D32, 0) | F32: =E32*B32
A33: Mamaearth Vitamin C Face Mask | B33: =Unit_Economics!B33 | C33: =Unit_Economics!M33 | D33: =B33-C33 | E33: =IF(D33>0, B1/D33, 0) | F33: =E33*B33
A34: Mamaearth Vitamin C Body Lotion | B34: =Unit_Economics!B34 | C34: =Unit_Economics!M34 | D34: =B34-C34 | E34: =IF(D34>0, B1/D34, 0) | F34: =E34*B34
A35: Mamaearth Ubtan Body Lotion | B35: =Unit_Economics!B35 | C35: =Unit_Economics!M35 | D35: =B35-C35 | E35: =IF(D35>0, B1/D35, 0) | F35: =E35*B35
A36: Mamaearth Cocoa Body Butter | B36: =Unit_Economics!B36 | C36: =Unit_Economics!M36 | D36: =B36-C36 | E36: =IF(D36>0, B1/D36, 0) | F36: =E36*B36
A37: Mamaearth Tea Tree Body Wash | B37: =Unit_Economics!B37 | C37: =Unit_Economics!M37 | D37: =B37-C37 | E37: =IF(D37>0, B1/D37, 0) | F37: =E37*B37
A38: Mamaearth Baby Shampoo | B38: =Unit_Economics!B38 | C38: =Unit_Economics!M38 | D38: =B38-C38 | E38: =IF(D38>0, B1/D38, 0) | F38: =E38*B38
A39: Mamaearth Baby Lotion | B39: =Unit_Economics!B39 | C39: =Unit_Economics!M39 | D39: =B39-C39 | E39: =IF(D39>0, B1/D39, 0) | F39: =E39*B39
A40: Mamaearth Baby Soap | B40: =Unit_Economics!B40 | C40: =Unit_Economics!M40 | D40: =B40-C40 | E40: =IF(D40>0, B1/D40, 0) | F40: =E40*B40
A41: Mamaearth Lip Balm | B41: =Unit_Economics!B41 | C41: =Unit_Economics!M41 | D41: =B41-C41 | E41: =IF(D41>0, B1/D41, 0) | F41: =E41*B41
...

Sheet Dashboard
A1: ONDC vs Amazon Unit Economics Dashboard
A3: Key Metrics
A4: Average Profit per Unit (Amazon) | B4: =AVERAGE(Unit_Economics!N2:N42)
A5: Average Profit per Unit (ONDC) | B5: =AVERAGE(Unit_Economics!O2:O42)
A6: Average Profit Increase % | B6: =AVERAGE(Unit_Economics!P2:P42)
A7: Total Monthly Profit (Amazon) | B7: =SUM(Unit_Economics!Q2:Q42)
A8: Total Monthly Profit (ONDC) | B8: =SUM(Unit_Economics!R2:R42)
A9: Total Monthly Profit Increase | B9: =E7-E6
A10: Best Performing Product (ONDC) | B10: =INDEX(Unit_Economics!A2:A42,MATCH(MAX(Unit_Economics!O2:O42),Unit_Economics!O2:O42,0))
A13: Charts
